{
 "cells": [
  {
   "cell_type": "markdown",
   "metadata": {
    "toc": true
   },
   "source": [
    "<h1>Table of Contents<span class=\"tocSkip\"></span></h1>\n",
    "<div class=\"toc\"><ul class=\"toc-item\"><li><span><a href=\"#Import-the-source-code-of-the-project\" data-toc-modified-id=\"Import-the-source-code-of-the-project-1\"><span class=\"toc-item-num\">1&nbsp;&nbsp;</span>Import the source code of the project</a></span></li><li><span><a href=\"#Import-and-use-the-functionality\" data-toc-modified-id=\"Import-and-use-the-functionality-2\"><span class=\"toc-item-num\">2&nbsp;&nbsp;</span>Import and use the functionality</a></span></li></ul></div>"
   ]
  },
  {
   "cell_type": "markdown",
   "metadata": {},
   "source": [
    "# Development with the notebook\n",
    "This notebook server can be used as a scratchpad. Work in progress code, algorithms, visualizations, tests, ...\n",
    "\n",
    "The ultimate goal here is to refactor these snippets in well documented and tested python classes and methods so they can be imported easily. \n",
    "\n",
    "The suggested workflow is as follows:\n",
    "1. Use the notebook to prototype and test drive your development\n",
    "2. Migrate your developed code into the project. Create a python file, organize it in classes,...\n",
    "3. Document your migrated code (docstring) so it's functionality is documented in the sphinx docs.\n",
    "4. Import the migrated code back into this notebook and develop tests around it.\n",
    "5. Include these tests in the project.\n",
    "6. Cleanup your notebook as the functionality is now in the python project and can be easily imported in the future.\n"
   ]
  },
  {
   "cell_type": "markdown",
   "metadata": {},
   "source": [
    "## Import the source code of the project\n",
    "Updates to the project's source need to be reflected here so it's possible to add new functionality and fix bugs which are directly reflected here. Jupyter supports this behaviour with the `autoreload` magic. \n",
    "\n",
    "The 2 cells below will setup this autoreload functionality (so the original import is not cached) and add the project path to the system path. Now the project source can be imported (without installing it as a python package)."
   ]
  },
  {
   "cell_type": "code",
   "execution_count": 7,
   "metadata": {
    "ExecuteTime": {
     "end_time": "2022-06-16T14:47:08.852940Z",
     "start_time": "2022-06-16T14:47:08.805966Z"
    }
   },
   "outputs": [
    {
     "name": "stderr",
     "output_type": "stream",
     "text": [
      "[autoreload of numpy.core failed: Traceback (most recent call last):\n",
      "  File \"/home/pita/Projects/py_fatigue/.venv/lib/python3.9/site-packages/IPython/extensions/autoreload.py\", line 276, in check\n",
      "    superreload(m, reload, self.old_objects)\n",
      "  File \"/home/pita/Projects/py_fatigue/.venv/lib/python3.9/site-packages/IPython/extensions/autoreload.py\", line 455, in superreload\n",
      "    if not append_obj(module, old_objects, name, obj):\n",
      "  File \"/home/pita/Projects/py_fatigue/.venv/lib/python3.9/site-packages/IPython/extensions/autoreload.py\", line 423, in append_obj\n",
      "    in_module = hasattr(obj, \"__module__\") and obj.__module__ == module.__name__\n",
      "  File \"/home/pita/Projects/py_fatigue/.venv/lib/python3.9/site-packages/numpy/core/defchararray.py\", line 2, in __getattr__\n",
      "    from numpy._core import defchararray\n",
      "  File \"/home/pita/Projects/py_fatigue/.venv/lib/python3.9/site-packages/numpy/_core/defchararray.py\", line 25, in <module>\n",
      "    from numpy.strings import *\n",
      "  File \"/home/pita/Projects/py_fatigue/.venv/lib/python3.9/site-packages/numpy/strings/__init__.py\", line 1, in <module>\n",
      "    from numpy._core.strings import __all__, __doc__\n",
      "  File \"/home/pita/Projects/py_fatigue/.venv/lib/python3.9/site-packages/numpy/_core/strings.py\", line 63, in <module>\n",
      "    MAX = np.iinfo(np.int64).max\n",
      "  File \"/home/pita/Projects/py_fatigue/.venv/lib/python3.9/site-packages/numpy/core/getlimits.py\", line 650, in __init__\n",
      "NameError: name 'numeric' is not defined\n",
      "]\n",
      "[autoreload of numpy.ma.core failed: Traceback (most recent call last):\n",
      "  File \"/home/pita/Projects/py_fatigue/.venv/lib/python3.9/site-packages/IPython/extensions/autoreload.py\", line 276, in check\n",
      "    superreload(m, reload, self.old_objects)\n",
      "  File \"/home/pita/Projects/py_fatigue/.venv/lib/python3.9/site-packages/IPython/extensions/autoreload.py\", line 475, in superreload\n",
      "    module = reload(module)\n",
      "  File \"/home/pita/.pyenv/versions/3.9.19/lib/python3.9/importlib/__init__.py\", line 169, in reload\n",
      "    _bootstrap._exec(spec, module)\n",
      "  File \"<frozen importlib._bootstrap>\", line 613, in _exec\n",
      "  File \"<frozen importlib._bootstrap_external>\", line 850, in exec_module\n",
      "  File \"<frozen importlib._bootstrap>\", line 228, in _call_with_frames_removed\n",
      "  File \"/home/pita/Projects/py_fatigue/.venv/lib/python3.9/site-packages/numpy/ma/core.py\", line 197, in <module>\n",
      "    elif np.issubdtype(scalar_dtype, np.integer):\n",
      "  File \"/home/pita/Projects/py_fatigue/.venv/lib/python3.9/site-packages/numpy/core/numerictypes.py\", line 415, in issubdtype\n",
      "NameError: name 'issubclass_' is not defined\n",
      "]\n",
      "[autoreload of numpy failed: Traceback (most recent call last):\n",
      "  File \"/home/pita/Projects/py_fatigue/.venv/lib/python3.9/site-packages/IPython/extensions/autoreload.py\", line 276, in check\n",
      "    superreload(m, reload, self.old_objects)\n",
      "  File \"/home/pita/Projects/py_fatigue/.venv/lib/python3.9/site-packages/IPython/extensions/autoreload.py\", line 455, in superreload\n",
      "    if not append_obj(module, old_objects, name, obj):\n",
      "  File \"/home/pita/Projects/py_fatigue/.venv/lib/python3.9/site-packages/IPython/extensions/autoreload.py\", line 423, in append_obj\n",
      "    in_module = hasattr(obj, \"__module__\") and obj.__module__ == module.__name__\n",
      "  File \"/home/pita/Projects/py_fatigue/.venv/lib/python3.9/site-packages/numpy/core/defchararray.py\", line 2, in __getattr__\n",
      "    from numpy._core import defchararray\n",
      "  File \"/home/pita/Projects/py_fatigue/.venv/lib/python3.9/site-packages/numpy/_core/defchararray.py\", line 25, in <module>\n",
      "    from numpy.strings import *\n",
      "  File \"/home/pita/Projects/py_fatigue/.venv/lib/python3.9/site-packages/numpy/strings/__init__.py\", line 1, in <module>\n",
      "    from numpy._core.strings import __all__, __doc__\n",
      "  File \"/home/pita/Projects/py_fatigue/.venv/lib/python3.9/site-packages/numpy/_core/strings.py\", line 63, in <module>\n",
      "    MAX = np.iinfo(np.int64).max\n",
      "  File \"/home/pita/Projects/py_fatigue/.venv/lib/python3.9/site-packages/numpy/core/getlimits.py\", line 650, in __init__\n",
      "NameError: name 'numeric' is not defined\n",
      "]\n",
      "[autoreload of pandas._libs.tslibs failed: Traceback (most recent call last):\n",
      "  File \"/home/pita/Projects/py_fatigue/.venv/lib/python3.9/site-packages/IPython/extensions/autoreload.py\", line 276, in check\n",
      "    superreload(m, reload, self.old_objects)\n",
      "  File \"/home/pita/Projects/py_fatigue/.venv/lib/python3.9/site-packages/IPython/extensions/autoreload.py\", line 475, in superreload\n",
      "    module = reload(module)\n",
      "  File \"/home/pita/.pyenv/versions/3.9.19/lib/python3.9/importlib/__init__.py\", line 169, in reload\n",
      "    _bootstrap._exec(spec, module)\n",
      "  File \"<frozen importlib._bootstrap>\", line 613, in _exec\n",
      "  File \"<frozen importlib._bootstrap_external>\", line 850, in exec_module\n",
      "  File \"<frozen importlib._bootstrap>\", line 228, in _call_with_frames_removed\n",
      "  File \"/home/pita/Projects/py_fatigue/.venv/lib/python3.9/site-packages/pandas/_libs/tslibs/__init__.py\", line 52, in <module>\n",
      "    from pandas._libs.tslibs.np_datetime import (\n",
      "ImportError: cannot import name 'add_overflowsafe' from 'pandas._libs.tslibs.np_datetime' (/home/pita/Projects/py_fatigue/.venv/lib/python3.9/site-packages/pandas/_libs/tslibs/np_datetime.cpython-39-x86_64-linux-gnu.so)\n",
      "]\n",
      "[autoreload of pandas.core.dtypes.dtypes failed: Traceback (most recent call last):\n",
      "  File \"/home/pita/Projects/py_fatigue/.venv/lib/python3.9/site-packages/IPython/extensions/autoreload.py\", line 276, in check\n",
      "    superreload(m, reload, self.old_objects)\n",
      "  File \"/home/pita/Projects/py_fatigue/.venv/lib/python3.9/site-packages/IPython/extensions/autoreload.py\", line 475, in superreload\n",
      "    module = reload(module)\n",
      "  File \"/home/pita/.pyenv/versions/3.9.19/lib/python3.9/importlib/__init__.py\", line 169, in reload\n",
      "    _bootstrap._exec(spec, module)\n",
      "  File \"<frozen importlib._bootstrap>\", line 613, in _exec\n",
      "  File \"<frozen importlib._bootstrap_external>\", line 850, in exec_module\n",
      "  File \"<frozen importlib._bootstrap>\", line 228, in _call_with_frames_removed\n",
      "  File \"/home/pita/Projects/py_fatigue/.venv/lib/python3.9/site-packages/pandas/core/dtypes/dtypes.py\", line 41, in <module>\n",
      "    from pandas._libs.tslibs.dtypes import (\n",
      "ImportError: cannot import name 'abbrev_to_npy_unit' from 'pandas._libs.tslibs.dtypes' (/home/pita/Projects/py_fatigue/.venv/lib/python3.9/site-packages/pandas/_libs/tslibs/dtypes.cpython-39-x86_64-linux-gnu.so)\n",
      "]\n",
      "[autoreload of pandas.core.dtypes.common failed: Traceback (most recent call last):\n",
      "  File \"/home/pita/Projects/py_fatigue/.venv/lib/python3.9/site-packages/IPython/extensions/autoreload.py\", line 276, in check\n",
      "    superreload(m, reload, self.old_objects)\n",
      "  File \"/home/pita/Projects/py_fatigue/.venv/lib/python3.9/site-packages/IPython/extensions/autoreload.py\", line 475, in superreload\n",
      "    module = reload(module)\n",
      "  File \"/home/pita/.pyenv/versions/3.9.19/lib/python3.9/importlib/__init__.py\", line 169, in reload\n",
      "    _bootstrap._exec(spec, module)\n",
      "  File \"<frozen importlib._bootstrap>\", line 613, in _exec\n",
      "  File \"<frozen importlib._bootstrap_external>\", line 850, in exec_module\n",
      "  File \"<frozen importlib._bootstrap>\", line 228, in _call_with_frames_removed\n",
      "  File \"/home/pita/Projects/py_fatigue/.venv/lib/python3.9/site-packages/pandas/core/dtypes/common.py\", line 25, in <module>\n",
      "    from pandas.core.dtypes.dtypes import (\n",
      "ImportError: cannot import name 'SparseDtype' from 'pandas.core.dtypes.dtypes' (/home/pita/Projects/py_fatigue/.venv/lib/python3.9/site-packages/pandas/core/dtypes/dtypes.py)\n",
      "]\n",
      "[autoreload of pandas.core.dtypes.astype failed: Traceback (most recent call last):\n",
      "  File \"/home/pita/Projects/py_fatigue/.venv/lib/python3.9/site-packages/IPython/extensions/autoreload.py\", line 276, in check\n",
      "    superreload(m, reload, self.old_objects)\n",
      "  File \"/home/pita/Projects/py_fatigue/.venv/lib/python3.9/site-packages/IPython/extensions/autoreload.py\", line 475, in superreload\n",
      "    module = reload(module)\n",
      "  File \"/home/pita/.pyenv/versions/3.9.19/lib/python3.9/importlib/__init__.py\", line 169, in reload\n",
      "    _bootstrap._exec(spec, module)\n",
      "  File \"<frozen importlib._bootstrap>\", line 613, in _exec\n",
      "  File \"<frozen importlib._bootstrap_external>\", line 850, in exec_module\n",
      "  File \"<frozen importlib._bootstrap>\", line 228, in _call_with_frames_removed\n",
      "  File \"/home/pita/Projects/py_fatigue/.venv/lib/python3.9/site-packages/pandas/core/dtypes/astype.py\", line 25, in <module>\n",
      "    from pandas.core.dtypes.dtypes import (\n",
      "ImportError: cannot import name 'NumpyEADtype' from 'pandas.core.dtypes.dtypes' (/home/pita/Projects/py_fatigue/.venv/lib/python3.9/site-packages/pandas/core/dtypes/dtypes.py)\n",
      "]\n",
      "[autoreload of pandas.core.dtypes.cast failed: Traceback (most recent call last):\n",
      "  File \"/home/pita/Projects/py_fatigue/.venv/lib/python3.9/site-packages/IPython/extensions/autoreload.py\", line 276, in check\n",
      "    superreload(m, reload, self.old_objects)\n",
      "  File \"/home/pita/Projects/py_fatigue/.venv/lib/python3.9/site-packages/IPython/extensions/autoreload.py\", line 475, in superreload\n",
      "    module = reload(module)\n",
      "  File \"/home/pita/.pyenv/versions/3.9.19/lib/python3.9/importlib/__init__.py\", line 169, in reload\n",
      "    _bootstrap._exec(spec, module)\n",
      "  File \"<frozen importlib._bootstrap>\", line 613, in _exec\n",
      "  File \"<frozen importlib._bootstrap_external>\", line 850, in exec_module\n",
      "  File \"<frozen importlib._bootstrap>\", line 228, in _call_with_frames_removed\n",
      "  File \"/home/pita/Projects/py_fatigue/.venv/lib/python3.9/site-packages/pandas/core/dtypes/cast.py\", line 33, in <module>\n",
      "    from pandas._libs.tslibs import (\n",
      "ImportError: cannot import name 'is_supported_dtype' from 'pandas._libs.tslibs' (/home/pita/Projects/py_fatigue/.venv/lib/python3.9/site-packages/pandas/_libs/tslibs/__init__.py)\n",
      "]\n",
      "[autoreload of pandas.core.dtypes.concat failed: Traceback (most recent call last):\n",
      "  File \"/home/pita/Projects/py_fatigue/.venv/lib/python3.9/site-packages/IPython/extensions/autoreload.py\", line 276, in check\n",
      "    superreload(m, reload, self.old_objects)\n",
      "  File \"/home/pita/Projects/py_fatigue/.venv/lib/python3.9/site-packages/IPython/extensions/autoreload.py\", line 475, in superreload\n",
      "    module = reload(module)\n",
      "  File \"/home/pita/.pyenv/versions/3.9.19/lib/python3.9/importlib/__init__.py\", line 169, in reload\n",
      "    _bootstrap._exec(spec, module)\n",
      "  File \"<frozen importlib._bootstrap>\", line 613, in _exec\n",
      "  File \"<frozen importlib._bootstrap_external>\", line 850, in exec_module\n",
      "  File \"<frozen importlib._bootstrap>\", line 228, in _call_with_frames_removed\n",
      "  File \"/home/pita/Projects/py_fatigue/.venv/lib/python3.9/site-packages/pandas/core/dtypes/concat.py\", line 18, in <module>\n",
      "    from pandas.core.dtypes.cast import (\n",
      "ImportError: cannot import name 'np_find_common_type' from 'pandas.core.dtypes.cast' (/home/pita/Projects/py_fatigue/.venv/lib/python3.9/site-packages/pandas/core/dtypes/cast.py)\n",
      "]\n",
      "[autoreload of pandas.core.construction failed: Traceback (most recent call last):\n",
      "  File \"/home/pita/Projects/py_fatigue/.venv/lib/python3.9/site-packages/IPython/extensions/autoreload.py\", line 276, in check\n",
      "    superreload(m, reload, self.old_objects)\n",
      "  File \"/home/pita/Projects/py_fatigue/.venv/lib/python3.9/site-packages/IPython/extensions/autoreload.py\", line 475, in superreload\n",
      "    module = reload(module)\n",
      "  File \"/home/pita/.pyenv/versions/3.9.19/lib/python3.9/importlib/__init__.py\", line 169, in reload\n",
      "    _bootstrap._exec(spec, module)\n",
      "  File \"<frozen importlib._bootstrap>\", line 613, in _exec\n",
      "  File \"<frozen importlib._bootstrap_external>\", line 850, in exec_module\n",
      "  File \"<frozen importlib._bootstrap>\", line 228, in _call_with_frames_removed\n",
      "  File \"/home/pita/Projects/py_fatigue/.venv/lib/python3.9/site-packages/pandas/core/construction.py\", line 25, in <module>\n",
      "    from pandas._libs.tslibs import (\n",
      "ImportError: cannot import name 'get_supported_dtype' from 'pandas._libs.tslibs' (/home/pita/Projects/py_fatigue/.venv/lib/python3.9/site-packages/pandas/_libs/tslibs/__init__.py)\n",
      "]\n",
      "[autoreload of pandas.core.algorithms failed: Traceback (most recent call last):\n",
      "  File \"/home/pita/Projects/py_fatigue/.venv/lib/python3.9/site-packages/IPython/extensions/autoreload.py\", line 276, in check\n",
      "    superreload(m, reload, self.old_objects)\n",
      "  File \"/home/pita/Projects/py_fatigue/.venv/lib/python3.9/site-packages/IPython/extensions/autoreload.py\", line 475, in superreload\n",
      "    module = reload(module)\n",
      "  File \"/home/pita/.pyenv/versions/3.9.19/lib/python3.9/importlib/__init__.py\", line 169, in reload\n",
      "    _bootstrap._exec(spec, module)\n",
      "  File \"<frozen importlib._bootstrap>\", line 613, in _exec\n",
      "  File \"<frozen importlib._bootstrap_external>\", line 850, in exec_module\n",
      "  File \"<frozen importlib._bootstrap>\", line 228, in _call_with_frames_removed\n",
      "  File \"/home/pita/Projects/py_fatigue/.venv/lib/python3.9/site-packages/pandas/core/algorithms.py\", line 36, in <module>\n",
      "    from pandas.core.dtypes.cast import (\n",
      "ImportError: cannot import name 'np_find_common_type' from 'pandas.core.dtypes.cast' (/home/pita/Projects/py_fatigue/.venv/lib/python3.9/site-packages/pandas/core/dtypes/cast.py)\n",
      "]\n",
      "[autoreload of pandas.core.ops.array_ops failed: Traceback (most recent call last):\n",
      "  File \"/home/pita/Projects/py_fatigue/.venv/lib/python3.9/site-packages/IPython/extensions/autoreload.py\", line 276, in check\n",
      "    superreload(m, reload, self.old_objects)\n",
      "  File \"/home/pita/Projects/py_fatigue/.venv/lib/python3.9/site-packages/IPython/extensions/autoreload.py\", line 475, in superreload\n",
      "    module = reload(module)\n",
      "  File \"/home/pita/.pyenv/versions/3.9.19/lib/python3.9/importlib/__init__.py\", line 169, in reload\n",
      "    _bootstrap._exec(spec, module)\n",
      "  File \"<frozen importlib._bootstrap>\", line 613, in _exec\n",
      "  File \"<frozen importlib._bootstrap_external>\", line 850, in exec_module\n",
      "  File \"<frozen importlib._bootstrap>\", line 228, in _call_with_frames_removed\n",
      "  File \"/home/pita/Projects/py_fatigue/.venv/lib/python3.9/site-packages/pandas/core/ops/array_ops.py\", line 25, in <module>\n",
      "    from pandas._libs.tslibs import (\n",
      "ImportError: cannot import name 'get_supported_dtype' from 'pandas._libs.tslibs' (/home/pita/Projects/py_fatigue/.venv/lib/python3.9/site-packages/pandas/_libs/tslibs/__init__.py)\n",
      "]\n",
      "[autoreload of pandas.core.ops failed: Traceback (most recent call last):\n",
      "  File \"/home/pita/Projects/py_fatigue/.venv/lib/python3.9/site-packages/IPython/extensions/autoreload.py\", line 276, in check\n",
      "    superreload(m, reload, self.old_objects)\n",
      "  File \"/home/pita/Projects/py_fatigue/.venv/lib/python3.9/site-packages/IPython/extensions/autoreload.py\", line 475, in superreload\n",
      "    module = reload(module)\n",
      "  File \"/home/pita/.pyenv/versions/3.9.19/lib/python3.9/importlib/__init__.py\", line 169, in reload\n",
      "    _bootstrap._exec(spec, module)\n",
      "  File \"<frozen importlib._bootstrap>\", line 613, in _exec\n",
      "  File \"<frozen importlib._bootstrap_external>\", line 850, in exec_module\n",
      "  File \"<frozen importlib._bootstrap>\", line 228, in _call_with_frames_removed\n",
      "  File \"/home/pita/Projects/py_fatigue/.venv/lib/python3.9/site-packages/pandas/core/ops/__init__.py\", line 8, in <module>\n",
      "    from pandas.core.ops.array_ops import (\n",
      "ImportError: cannot import name 'fill_binop' from 'pandas.core.ops.array_ops' (/home/pita/Projects/py_fatigue/.venv/lib/python3.9/site-packages/pandas/core/ops/array_ops.py)\n",
      "]\n",
      "[autoreload of pandas.core.arrays.base failed: Traceback (most recent call last):\n",
      "  File \"/home/pita/Projects/py_fatigue/.venv/lib/python3.9/site-packages/IPython/extensions/autoreload.py\", line 276, in check\n",
      "    superreload(m, reload, self.old_objects)\n",
      "  File \"/home/pita/Projects/py_fatigue/.venv/lib/python3.9/site-packages/IPython/extensions/autoreload.py\", line 475, in superreload\n",
      "    module = reload(module)\n",
      "  File \"/home/pita/.pyenv/versions/3.9.19/lib/python3.9/importlib/__init__.py\", line 169, in reload\n",
      "    _bootstrap._exec(spec, module)\n",
      "  File \"<frozen importlib._bootstrap>\", line 613, in _exec\n",
      "  File \"<frozen importlib._bootstrap_external>\", line 850, in exec_module\n",
      "  File \"<frozen importlib._bootstrap>\", line 228, in _call_with_frames_removed\n",
      "  File \"/home/pita/Projects/py_fatigue/.venv/lib/python3.9/site-packages/pandas/core/arrays/base.py\", line 63, in <module>\n",
      "    from pandas.core.algorithms import (\n",
      "ImportError: cannot import name 'map_array' from 'pandas.core.algorithms' (/home/pita/Projects/py_fatigue/.venv/lib/python3.9/site-packages/pandas/core/algorithms.py)\n",
      "]\n",
      "[autoreload of pandas.core.arrays.arrow.array failed: Traceback (most recent call last):\n",
      "  File \"/home/pita/Projects/py_fatigue/.venv/lib/python3.9/site-packages/IPython/extensions/autoreload.py\", line 276, in check\n",
      "    superreload(m, reload, self.old_objects)\n",
      "  File \"/home/pita/Projects/py_fatigue/.venv/lib/python3.9/site-packages/IPython/extensions/autoreload.py\", line 475, in superreload\n",
      "    module = reload(module)\n",
      "  File \"/home/pita/.pyenv/versions/3.9.19/lib/python3.9/importlib/__init__.py\", line 169, in reload\n",
      "    _bootstrap._exec(spec, module)\n",
      "  File \"<frozen importlib._bootstrap>\", line 613, in _exec\n",
      "  File \"<frozen importlib._bootstrap_external>\", line 850, in exec_module\n",
      "  File \"<frozen importlib._bootstrap>\", line 228, in _call_with_frames_removed\n",
      "  File \"/home/pita/Projects/py_fatigue/.venv/lib/python3.9/site-packages/pandas/core/arrays/arrow/array.py\", line 56, in <module>\n",
      "    from pandas.core.algorithms import map_array\n",
      "ImportError: cannot import name 'map_array' from 'pandas.core.algorithms' (/home/pita/Projects/py_fatigue/.venv/lib/python3.9/site-packages/pandas/core/algorithms.py)\n",
      "]\n",
      "[autoreload of pandas.core.nanops failed: Traceback (most recent call last):\n",
      "  File \"/home/pita/Projects/py_fatigue/.venv/lib/python3.9/site-packages/IPython/extensions/autoreload.py\", line 276, in check\n",
      "    superreload(m, reload, self.old_objects)\n",
      "  File \"/home/pita/Projects/py_fatigue/.venv/lib/python3.9/site-packages/IPython/extensions/autoreload.py\", line 500, in superreload\n",
      "    update_generic(old_obj, new_obj)\n",
      "  File \"/home/pita/Projects/py_fatigue/.venv/lib/python3.9/site-packages/IPython/extensions/autoreload.py\", line 397, in update_generic\n",
      "    update(a, b)\n",
      "  File \"/home/pita/Projects/py_fatigue/.venv/lib/python3.9/site-packages/IPython/extensions/autoreload.py\", line 309, in update_function\n",
      "    setattr(old, name, getattr(new, name))\n",
      "ValueError: nanmean() requires a code object with 2 free vars, not 4\n",
      "]\n",
      "[autoreload of pandas.core.arrays.masked failed: Traceback (most recent call last):\n",
      "  File \"/home/pita/Projects/py_fatigue/.venv/lib/python3.9/site-packages/IPython/extensions/autoreload.py\", line 276, in check\n",
      "    superreload(m, reload, self.old_objects)\n",
      "  File \"/home/pita/Projects/py_fatigue/.venv/lib/python3.9/site-packages/IPython/extensions/autoreload.py\", line 475, in superreload\n",
      "    module = reload(module)\n",
      "  File \"/home/pita/.pyenv/versions/3.9.19/lib/python3.9/importlib/__init__.py\", line 169, in reload\n",
      "    _bootstrap._exec(spec, module)\n",
      "  File \"<frozen importlib._bootstrap>\", line 613, in _exec\n",
      "  File \"<frozen importlib._bootstrap_external>\", line 850, in exec_module\n",
      "  File \"<frozen importlib._bootstrap>\", line 228, in _call_with_frames_removed\n",
      "  File \"/home/pita/Projects/py_fatigue/.venv/lib/python3.9/site-packages/pandas/core/arrays/masked.py\", line 18, in <module>\n",
      "    from pandas._libs.tslibs import is_supported_dtype\n",
      "ImportError: cannot import name 'is_supported_dtype' from 'pandas._libs.tslibs' (/home/pita/Projects/py_fatigue/.venv/lib/python3.9/site-packages/pandas/_libs/tslibs/__init__.py)\n",
      "]\n",
      "[autoreload of pandas.core.arrays.boolean failed: Traceback (most recent call last):\n",
      "  File \"/home/pita/Projects/py_fatigue/.venv/lib/python3.9/site-packages/IPython/extensions/autoreload.py\", line 276, in check\n",
      "    superreload(m, reload, self.old_objects)\n",
      "  File \"/home/pita/Projects/py_fatigue/.venv/lib/python3.9/site-packages/IPython/extensions/autoreload.py\", line 475, in superreload\n",
      "    module = reload(module)\n",
      "  File \"/home/pita/.pyenv/versions/3.9.19/lib/python3.9/importlib/__init__.py\", line 169, in reload\n",
      "    _bootstrap._exec(spec, module)\n",
      "  File \"<frozen importlib._bootstrap>\", line 613, in _exec\n",
      "  File \"<frozen importlib._bootstrap_external>\", line 850, in exec_module\n",
      "  File \"<frozen importlib._bootstrap>\", line 228, in _call_with_frames_removed\n",
      "  File \"/home/pita/Projects/py_fatigue/.venv/lib/python3.9/site-packages/pandas/core/arrays/boolean.py\", line 41, in <module>\n",
      "    class BooleanDtype(BaseMaskedDtype):\n",
      "  File \"/home/pita/Projects/py_fatigue/.venv/lib/python3.9/site-packages/pandas/core/dtypes/base.py\", line 497, in register_extension_dtype\n",
      "    _registry.register(cls)\n",
      "  File \"/home/pita/Projects/py_fatigue/.venv/lib/python3.9/site-packages/pandas/core/dtypes/base.py\", line 527, in register\n",
      "    raise ValueError(\"can only register pandas extension dtypes\")\n",
      "ValueError: can only register pandas extension dtypes\n",
      "]\n",
      "[autoreload of pandas.core.arrays._mixins failed: Traceback (most recent call last):\n",
      "  File \"/home/pita/Projects/py_fatigue/.venv/lib/python3.9/site-packages/IPython/extensions/autoreload.py\", line 276, in check\n",
      "    superreload(m, reload, self.old_objects)\n",
      "  File \"/home/pita/Projects/py_fatigue/.venv/lib/python3.9/site-packages/IPython/extensions/autoreload.py\", line 475, in superreload\n",
      "    module = reload(module)\n",
      "  File \"/home/pita/.pyenv/versions/3.9.19/lib/python3.9/importlib/__init__.py\", line 169, in reload\n",
      "    _bootstrap._exec(spec, module)\n",
      "  File \"<frozen importlib._bootstrap>\", line 613, in _exec\n",
      "  File \"<frozen importlib._bootstrap_external>\", line 850, in exec_module\n",
      "  File \"<frozen importlib._bootstrap>\", line 228, in _call_with_frames_removed\n",
      "  File \"/home/pita/Projects/py_fatigue/.venv/lib/python3.9/site-packages/pandas/core/arrays/_mixins.py\", line 16, in <module>\n",
      "    from pandas._libs.tslibs import is_supported_dtype\n",
      "ImportError: cannot import name 'is_supported_dtype' from 'pandas._libs.tslibs' (/home/pita/Projects/py_fatigue/.venv/lib/python3.9/site-packages/pandas/_libs/tslibs/__init__.py)\n",
      "]\n",
      "[autoreload of pandas.core.strings.accessor failed: Traceback (most recent call last):\n",
      "  File \"/home/pita/Projects/py_fatigue/.venv/lib/python3.9/site-packages/IPython/extensions/autoreload.py\", line 276, in check\n",
      "    superreload(m, reload, self.old_objects)\n",
      "  File \"/home/pita/Projects/py_fatigue/.venv/lib/python3.9/site-packages/IPython/extensions/autoreload.py\", line 475, in superreload\n",
      "    module = reload(module)\n",
      "  File \"/home/pita/.pyenv/versions/3.9.19/lib/python3.9/importlib/__init__.py\", line 169, in reload\n",
      "    _bootstrap._exec(spec, module)\n",
      "  File \"<frozen importlib._bootstrap>\", line 613, in _exec\n",
      "  File \"<frozen importlib._bootstrap_external>\", line 850, in exec_module\n",
      "  File \"<frozen importlib._bootstrap>\", line 228, in _call_with_frames_removed\n",
      "  File \"/home/pita/Projects/py_fatigue/.venv/lib/python3.9/site-packages/pandas/core/strings/accessor.py\", line 35, in <module>\n",
      "    from pandas.core.dtypes.dtypes import (\n",
      "ImportError: cannot import name 'ArrowDtype' from 'pandas.core.dtypes.dtypes' (/home/pita/Projects/py_fatigue/.venv/lib/python3.9/site-packages/pandas/core/dtypes/dtypes.py)\n",
      "]\n",
      "[autoreload of pandas.core.arrays.categorical failed: Traceback (most recent call last):\n",
      "  File \"/home/pita/Projects/py_fatigue/.venv/lib/python3.9/site-packages/IPython/extensions/autoreload.py\", line 276, in check\n",
      "    superreload(m, reload, self.old_objects)\n",
      "  File \"/home/pita/Projects/py_fatigue/.venv/lib/python3.9/site-packages/IPython/extensions/autoreload.py\", line 475, in superreload\n",
      "    module = reload(module)\n",
      "  File \"/home/pita/.pyenv/versions/3.9.19/lib/python3.9/importlib/__init__.py\", line 169, in reload\n",
      "    _bootstrap._exec(spec, module)\n",
      "  File \"<frozen importlib._bootstrap>\", line 613, in _exec\n",
      "  File \"<frozen importlib._bootstrap_external>\", line 850, in exec_module\n",
      "  File \"<frozen importlib._bootstrap>\", line 228, in _call_with_frames_removed\n",
      "  File \"/home/pita/Projects/py_fatigue/.venv/lib/python3.9/site-packages/pandas/core/arrays/categorical.py\", line 33, in <module>\n",
      "    from pandas.core.dtypes.common import (\n",
      "ImportError: cannot import name 'is_any_real_numeric_dtype' from 'pandas.core.dtypes.common' (/home/pita/Projects/py_fatigue/.venv/lib/python3.9/site-packages/pandas/core/dtypes/common.py)\n",
      "]\n",
      "[autoreload of pandas.core.arrays.integer failed: Traceback (most recent call last):\n",
      "  File \"/home/pita/Projects/py_fatigue/.venv/lib/python3.9/site-packages/IPython/extensions/autoreload.py\", line 276, in check\n",
      "    superreload(m, reload, self.old_objects)\n",
      "  File \"/home/pita/Projects/py_fatigue/.venv/lib/python3.9/site-packages/IPython/extensions/autoreload.py\", line 475, in superreload\n",
      "    module = reload(module)\n",
      "  File \"/home/pita/.pyenv/versions/3.9.19/lib/python3.9/importlib/__init__.py\", line 169, in reload\n",
      "    _bootstrap._exec(spec, module)\n",
      "  File \"<frozen importlib._bootstrap>\", line 613, in _exec\n",
      "  File \"<frozen importlib._bootstrap_external>\", line 850, in exec_module\n",
      "  File \"<frozen importlib._bootstrap>\", line 228, in _call_with_frames_removed\n",
      "  File \"/home/pita/Projects/py_fatigue/.venv/lib/python3.9/site-packages/pandas/core/arrays/integer.py\", line 208, in <module>\n",
      "    class Int8Dtype(IntegerDtype):\n",
      "  File \"/home/pita/Projects/py_fatigue/.venv/lib/python3.9/site-packages/pandas/core/dtypes/base.py\", line 497, in register_extension_dtype\n",
      "    _registry.register(cls)\n",
      "  File \"/home/pita/Projects/py_fatigue/.venv/lib/python3.9/site-packages/pandas/core/dtypes/base.py\", line 527, in register\n",
      "    raise ValueError(\"can only register pandas extension dtypes\")\n",
      "ValueError: can only register pandas extension dtypes\n",
      "]\n",
      "[autoreload of pandas.tseries.frequencies failed: Traceback (most recent call last):\n",
      "  File \"/home/pita/Projects/py_fatigue/.venv/lib/python3.9/site-packages/IPython/extensions/autoreload.py\", line 276, in check\n",
      "    superreload(m, reload, self.old_objects)\n",
      "  File \"/home/pita/Projects/py_fatigue/.venv/lib/python3.9/site-packages/IPython/extensions/autoreload.py\", line 475, in superreload\n",
      "    module = reload(module)\n",
      "  File \"/home/pita/.pyenv/versions/3.9.19/lib/python3.9/importlib/__init__.py\", line 169, in reload\n",
      "    _bootstrap._exec(spec, module)\n",
      "  File \"<frozen importlib._bootstrap>\", line 613, in _exec\n",
      "  File \"<frozen importlib._bootstrap_external>\", line 850, in exec_module\n",
      "  File \"<frozen importlib._bootstrap>\", line 228, in _call_with_frames_removed\n",
      "  File \"/home/pita/Projects/py_fatigue/.venv/lib/python3.9/site-packages/pandas/tseries/frequencies.py\", line 22, in <module>\n",
      "    from pandas._libs.tslibs.dtypes import (\n",
      "ImportError: cannot import name 'OFFSET_TO_PERIOD_FREQSTR' from 'pandas._libs.tslibs.dtypes' (/home/pita/Projects/py_fatigue/.venv/lib/python3.9/site-packages/pandas/_libs/tslibs/dtypes.cpython-39-x86_64-linux-gnu.so)\n",
      "]\n",
      "[autoreload of pandas.core.arrays.datetimelike failed: Traceback (most recent call last):\n",
      "  File \"/home/pita/Projects/py_fatigue/.venv/lib/python3.9/site-packages/IPython/extensions/autoreload.py\", line 276, in check\n",
      "    superreload(m, reload, self.old_objects)\n",
      "  File \"/home/pita/Projects/py_fatigue/.venv/lib/python3.9/site-packages/IPython/extensions/autoreload.py\", line 475, in superreload\n",
      "    module = reload(module)\n",
      "  File \"/home/pita/.pyenv/versions/3.9.19/lib/python3.9/importlib/__init__.py\", line 169, in reload\n",
      "    _bootstrap._exec(spec, module)\n",
      "  File \"<frozen importlib._bootstrap>\", line 613, in _exec\n",
      "  File \"<frozen importlib._bootstrap_external>\", line 850, in exec_module\n",
      "  File \"<frozen importlib._bootstrap>\", line 228, in _call_with_frames_removed\n",
      "  File \"/home/pita/Projects/py_fatigue/.venv/lib/python3.9/site-packages/pandas/core/arrays/datetimelike.py\", line 28, in <module>\n",
      "    from pandas._libs.tslibs import (\n",
      "ImportError: cannot import name 'add_overflowsafe' from 'pandas._libs.tslibs' (/home/pita/Projects/py_fatigue/.venv/lib/python3.9/site-packages/pandas/_libs/tslibs/__init__.py)\n",
      "]\n",
      "[autoreload of pandas.core.arrays.datetimes failed: Traceback (most recent call last):\n",
      "  File \"/home/pita/Projects/py_fatigue/.venv/lib/python3.9/site-packages/IPython/extensions/autoreload.py\", line 276, in check\n",
      "    superreload(m, reload, self.old_objects)\n",
      "  File \"/home/pita/Projects/py_fatigue/.venv/lib/python3.9/site-packages/IPython/extensions/autoreload.py\", line 475, in superreload\n",
      "    module = reload(module)\n",
      "  File \"/home/pita/.pyenv/versions/3.9.19/lib/python3.9/importlib/__init__.py\", line 169, in reload\n",
      "    _bootstrap._exec(spec, module)\n",
      "  File \"<frozen importlib._bootstrap>\", line 613, in _exec\n",
      "  File \"<frozen importlib._bootstrap_external>\", line 850, in exec_module\n",
      "  File \"<frozen importlib._bootstrap>\", line 228, in _call_with_frames_removed\n",
      "  File \"/home/pita/Projects/py_fatigue/.venv/lib/python3.9/site-packages/pandas/core/arrays/datetimes.py\", line 21, in <module>\n",
      "    from pandas._libs.tslibs import (\n",
      "ImportError: cannot import name 'get_supported_dtype' from 'pandas._libs.tslibs' (/home/pita/Projects/py_fatigue/.venv/lib/python3.9/site-packages/pandas/_libs/tslibs/__init__.py)\n",
      "]\n",
      "[autoreload of pandas.core.arrays.floating failed: Traceback (most recent call last):\n",
      "  File \"/home/pita/Projects/py_fatigue/.venv/lib/python3.9/site-packages/IPython/extensions/autoreload.py\", line 276, in check\n",
      "    superreload(m, reload, self.old_objects)\n",
      "  File \"/home/pita/Projects/py_fatigue/.venv/lib/python3.9/site-packages/IPython/extensions/autoreload.py\", line 475, in superreload\n",
      "    module = reload(module)\n",
      "  File \"/home/pita/.pyenv/versions/3.9.19/lib/python3.9/importlib/__init__.py\", line 169, in reload\n",
      "    _bootstrap._exec(spec, module)\n",
      "  File \"<frozen importlib._bootstrap>\", line 613, in _exec\n",
      "  File \"<frozen importlib._bootstrap_external>\", line 850, in exec_module\n",
      "  File \"<frozen importlib._bootstrap>\", line 228, in _call_with_frames_removed\n",
      "  File \"/home/pita/Projects/py_fatigue/.venv/lib/python3.9/site-packages/pandas/core/arrays/floating.py\", line 157, in <module>\n",
      "    class Float32Dtype(FloatingDtype):\n",
      "  File \"/home/pita/Projects/py_fatigue/.venv/lib/python3.9/site-packages/pandas/core/dtypes/base.py\", line 497, in register_extension_dtype\n",
      "    _registry.register(cls)\n",
      "  File \"/home/pita/Projects/py_fatigue/.venv/lib/python3.9/site-packages/pandas/core/dtypes/base.py\", line 527, in register\n",
      "    raise ValueError(\"can only register pandas extension dtypes\")\n",
      "ValueError: can only register pandas extension dtypes\n",
      "]\n",
      "[autoreload of pandas.core.arrays.sparse.array failed: Traceback (most recent call last):\n",
      "  File \"/home/pita/Projects/py_fatigue/.venv/lib/python3.9/site-packages/IPython/extensions/autoreload.py\", line 276, in check\n",
      "    superreload(m, reload, self.old_objects)\n",
      "  File \"/home/pita/Projects/py_fatigue/.venv/lib/python3.9/site-packages/IPython/extensions/autoreload.py\", line 475, in superreload\n",
      "    module = reload(module)\n",
      "  File \"/home/pita/.pyenv/versions/3.9.19/lib/python3.9/importlib/__init__.py\", line 169, in reload\n",
      "    _bootstrap._exec(spec, module)\n",
      "  File \"<frozen importlib._bootstrap>\", line 613, in _exec\n",
      "  File \"<frozen importlib._bootstrap_external>\", line 850, in exec_module\n",
      "  File \"<frozen importlib._bootstrap>\", line 228, in _call_with_frames_removed\n",
      "  File \"/home/pita/Projects/py_fatigue/.venv/lib/python3.9/site-packages/pandas/core/arrays/sparse/array.py\", line 53, in <module>\n",
      "    from pandas.core.dtypes.dtypes import (\n",
      "ImportError: cannot import name 'SparseDtype' from 'pandas.core.dtypes.dtypes' (/home/pita/Projects/py_fatigue/.venv/lib/python3.9/site-packages/pandas/core/dtypes/dtypes.py)\n",
      "]\n",
      "[autoreload of pandas.core.arrays.sparse.accessor failed: Traceback (most recent call last):\n",
      "  File \"/home/pita/Projects/py_fatigue/.venv/lib/python3.9/site-packages/IPython/extensions/autoreload.py\", line 276, in check\n",
      "    superreload(m, reload, self.old_objects)\n",
      "  File \"/home/pita/Projects/py_fatigue/.venv/lib/python3.9/site-packages/IPython/extensions/autoreload.py\", line 475, in superreload\n",
      "    module = reload(module)\n",
      "  File \"/home/pita/.pyenv/versions/3.9.19/lib/python3.9/importlib/__init__.py\", line 169, in reload\n",
      "    _bootstrap._exec(spec, module)\n",
      "  File \"<frozen importlib._bootstrap>\", line 613, in _exec\n",
      "  File \"<frozen importlib._bootstrap_external>\", line 850, in exec_module\n",
      "  File \"<frozen importlib._bootstrap>\", line 228, in _call_with_frames_removed\n",
      "  File \"/home/pita/Projects/py_fatigue/.venv/lib/python3.9/site-packages/pandas/core/arrays/sparse/accessor.py\", line 11, in <module>\n",
      "    from pandas.core.dtypes.dtypes import SparseDtype\n",
      "ImportError: cannot import name 'SparseDtype' from 'pandas.core.dtypes.dtypes' (/home/pita/Projects/py_fatigue/.venv/lib/python3.9/site-packages/pandas/core/dtypes/dtypes.py)\n",
      "]\n",
      "[autoreload of pandas.core.arrays.numpy_ failed: Traceback (most recent call last):\n",
      "  File \"/home/pita/Projects/py_fatigue/.venv/lib/python3.9/site-packages/IPython/extensions/autoreload.py\", line 276, in check\n",
      "    superreload(m, reload, self.old_objects)\n",
      "  File \"/home/pita/Projects/py_fatigue/.venv/lib/python3.9/site-packages/IPython/extensions/autoreload.py\", line 475, in superreload\n",
      "    module = reload(module)\n",
      "  File \"/home/pita/.pyenv/versions/3.9.19/lib/python3.9/importlib/__init__.py\", line 169, in reload\n",
      "    _bootstrap._exec(spec, module)\n",
      "  File \"<frozen importlib._bootstrap>\", line 613, in _exec\n",
      "  File \"<frozen importlib._bootstrap_external>\", line 850, in exec_module\n",
      "  File \"<frozen importlib._bootstrap>\", line 228, in _call_with_frames_removed\n",
      "  File \"/home/pita/Projects/py_fatigue/.venv/lib/python3.9/site-packages/pandas/core/arrays/numpy_.py\", line 11, in <module>\n",
      "    from pandas._libs.tslibs import is_supported_dtype\n",
      "ImportError: cannot import name 'is_supported_dtype' from 'pandas._libs.tslibs' (/home/pita/Projects/py_fatigue/.venv/lib/python3.9/site-packages/pandas/_libs/tslibs/__init__.py)\n",
      "]\n",
      "[autoreload of pandas.core.arrays.string_ failed: Traceback (most recent call last):\n",
      "  File \"/home/pita/Projects/py_fatigue/.venv/lib/python3.9/site-packages/IPython/extensions/autoreload.py\", line 276, in check\n",
      "    superreload(m, reload, self.old_objects)\n",
      "  File \"/home/pita/Projects/py_fatigue/.venv/lib/python3.9/site-packages/IPython/extensions/autoreload.py\", line 475, in superreload\n",
      "    module = reload(module)\n",
      "  File \"/home/pita/.pyenv/versions/3.9.19/lib/python3.9/importlib/__init__.py\", line 169, in reload\n",
      "    _bootstrap._exec(spec, module)\n",
      "  File \"<frozen importlib._bootstrap>\", line 613, in _exec\n",
      "  File \"<frozen importlib._bootstrap_external>\", line 850, in exec_module\n",
      "  File \"<frozen importlib._bootstrap>\", line 228, in _call_with_frames_removed\n",
      "  File \"/home/pita/Projects/py_fatigue/.venv/lib/python3.9/site-packages/pandas/core/arrays/string_.py\", line 48, in <module>\n",
      "    from pandas.core.arrays.numpy_ import NumpyExtensionArray\n",
      "ImportError: cannot import name 'NumpyExtensionArray' from 'pandas.core.arrays.numpy_' (/home/pita/Projects/py_fatigue/.venv/lib/python3.9/site-packages/pandas/core/arrays/numpy_.py)\n",
      "]\n",
      "[autoreload of pandas.core.indexes.base failed: Traceback (most recent call last):\n",
      "  File \"/home/pita/Projects/py_fatigue/.venv/lib/python3.9/site-packages/IPython/extensions/autoreload.py\", line 276, in check\n",
      "    superreload(m, reload, self.old_objects)\n",
      "  File \"/home/pita/Projects/py_fatigue/.venv/lib/python3.9/site-packages/IPython/extensions/autoreload.py\", line 475, in superreload\n",
      "    module = reload(module)\n",
      "  File \"/home/pita/.pyenv/versions/3.9.19/lib/python3.9/importlib/__init__.py\", line 169, in reload\n",
      "    _bootstrap._exec(spec, module)\n",
      "  File \"<frozen importlib._bootstrap>\", line 613, in _exec\n",
      "  File \"<frozen importlib._bootstrap_external>\", line 850, in exec_module\n",
      "  File \"<frozen importlib._bootstrap>\", line 228, in _call_with_frames_removed\n",
      "  File \"/home/pita/Projects/py_fatigue/.venv/lib/python3.9/site-packages/pandas/core/indexes/base.py\", line 36, in <module>\n",
      "    from pandas._libs.internals import BlockValuesRefs\n",
      "ImportError: cannot import name 'BlockValuesRefs' from 'pandas._libs.internals' (/home/pita/Projects/py_fatigue/.venv/lib/python3.9/site-packages/pandas/_libs/internals.cpython-39-x86_64-linux-gnu.so)\n",
      "]\n",
      "[autoreload of pandas.core.arrays.interval failed: Traceback (most recent call last):\n",
      "  File \"/home/pita/Projects/py_fatigue/.venv/lib/python3.9/site-packages/IPython/extensions/autoreload.py\", line 276, in check\n",
      "    superreload(m, reload, self.old_objects)\n",
      "  File \"/home/pita/Projects/py_fatigue/.venv/lib/python3.9/site-packages/IPython/extensions/autoreload.py\", line 475, in superreload\n",
      "    module = reload(module)\n",
      "  File \"/home/pita/.pyenv/versions/3.9.19/lib/python3.9/importlib/__init__.py\", line 169, in reload\n",
      "    _bootstrap._exec(spec, module)\n",
      "  File \"<frozen importlib._bootstrap>\", line 613, in _exec\n",
      "  File \"<frozen importlib._bootstrap_external>\", line 850, in exec_module\n",
      "  File \"<frozen importlib._bootstrap>\", line 228, in _call_with_frames_removed\n",
      "  File \"/home/pita/Projects/py_fatigue/.venv/lib/python3.9/site-packages/pandas/core/arrays/interval.py\", line 46, in <module>\n",
      "    from pandas.core.dtypes.cast import (\n",
      "ImportError: cannot import name 'maybe_upcast_numeric_to_64bit' from 'pandas.core.dtypes.cast' (/home/pita/Projects/py_fatigue/.venv/lib/python3.9/site-packages/pandas/core/dtypes/cast.py)\n",
      "]\n",
      "[autoreload of pandas.core.arrays.period failed: Traceback (most recent call last):\n",
      "  File \"/home/pita/Projects/py_fatigue/.venv/lib/python3.9/site-packages/IPython/extensions/autoreload.py\", line 276, in check\n",
      "    superreload(m, reload, self.old_objects)\n",
      "  File \"/home/pita/Projects/py_fatigue/.venv/lib/python3.9/site-packages/IPython/extensions/autoreload.py\", line 475, in superreload\n",
      "    module = reload(module)\n",
      "  File \"/home/pita/.pyenv/versions/3.9.19/lib/python3.9/importlib/__init__.py\", line 169, in reload\n",
      "    _bootstrap._exec(spec, module)\n",
      "  File \"<frozen importlib._bootstrap>\", line 613, in _exec\n",
      "  File \"<frozen importlib._bootstrap_external>\", line 850, in exec_module\n",
      "  File \"<frozen importlib._bootstrap>\", line 228, in _call_with_frames_removed\n",
      "  File \"/home/pita/Projects/py_fatigue/.venv/lib/python3.9/site-packages/pandas/core/arrays/period.py\", line 23, in <module>\n",
      "    from pandas._libs.tslibs import (\n",
      "ImportError: cannot import name 'add_overflowsafe' from 'pandas._libs.tslibs' (/home/pita/Projects/py_fatigue/.venv/lib/python3.9/site-packages/pandas/_libs/tslibs/__init__.py)\n",
      "]\n",
      "[autoreload of pandas.core.arrays.string_arrow failed: Traceback (most recent call last):\n",
      "  File \"/home/pita/Projects/py_fatigue/.venv/lib/python3.9/site-packages/IPython/extensions/autoreload.py\", line 276, in check\n",
      "    superreload(m, reload, self.old_objects)\n",
      "  File \"/home/pita/Projects/py_fatigue/.venv/lib/python3.9/site-packages/IPython/extensions/autoreload.py\", line 500, in superreload\n",
      "    update_generic(old_obj, new_obj)\n",
      "  File \"/home/pita/Projects/py_fatigue/.venv/lib/python3.9/site-packages/IPython/extensions/autoreload.py\", line 397, in update_generic\n",
      "    update(a, b)\n",
      "  File \"/home/pita/Projects/py_fatigue/.venv/lib/python3.9/site-packages/IPython/extensions/autoreload.py\", line 349, in update_class\n",
      "    if update_generic(old_obj, new_obj):\n",
      "  File \"/home/pita/Projects/py_fatigue/.venv/lib/python3.9/site-packages/IPython/extensions/autoreload.py\", line 397, in update_generic\n",
      "    update(a, b)\n",
      "  File \"/home/pita/Projects/py_fatigue/.venv/lib/python3.9/site-packages/IPython/extensions/autoreload.py\", line 309, in update_function\n",
      "    setattr(old, name, getattr(new, name))\n",
      "ValueError: _maybe_convert_setitem_value() requires a code object with 0 free vars, not 1\n",
      "]\n",
      "[autoreload of pandas.core.arrays.timedeltas failed: Traceback (most recent call last):\n",
      "  File \"/home/pita/Projects/py_fatigue/.venv/lib/python3.9/site-packages/IPython/extensions/autoreload.py\", line 276, in check\n",
      "    superreload(m, reload, self.old_objects)\n",
      "  File \"/home/pita/Projects/py_fatigue/.venv/lib/python3.9/site-packages/IPython/extensions/autoreload.py\", line 475, in superreload\n",
      "    module = reload(module)\n",
      "  File \"/home/pita/.pyenv/versions/3.9.19/lib/python3.9/importlib/__init__.py\", line 169, in reload\n",
      "    _bootstrap._exec(spec, module)\n",
      "  File \"<frozen importlib._bootstrap>\", line 613, in _exec\n",
      "  File \"<frozen importlib._bootstrap_external>\", line 850, in exec_module\n",
      "  File \"<frozen importlib._bootstrap>\", line 228, in _call_with_frames_removed\n",
      "  File \"/home/pita/Projects/py_fatigue/.venv/lib/python3.9/site-packages/pandas/core/arrays/timedeltas.py\", line 16, in <module>\n",
      "    from pandas._libs.tslibs import (\n",
      "ImportError: cannot import name 'get_supported_dtype' from 'pandas._libs.tslibs' (/home/pita/Projects/py_fatigue/.venv/lib/python3.9/site-packages/pandas/_libs/tslibs/__init__.py)\n",
      "]\n",
      "[autoreload of pandas.core.arrays failed: Traceback (most recent call last):\n",
      "  File \"/home/pita/Projects/py_fatigue/.venv/lib/python3.9/site-packages/IPython/extensions/autoreload.py\", line 276, in check\n",
      "    superreload(m, reload, self.old_objects)\n",
      "  File \"/home/pita/Projects/py_fatigue/.venv/lib/python3.9/site-packages/IPython/extensions/autoreload.py\", line 475, in superreload\n",
      "    module = reload(module)\n",
      "  File \"/home/pita/.pyenv/versions/3.9.19/lib/python3.9/importlib/__init__.py\", line 169, in reload\n",
      "    _bootstrap._exec(spec, module)\n",
      "  File \"<frozen importlib._bootstrap>\", line 613, in _exec\n",
      "  File \"<frozen importlib._bootstrap_external>\", line 850, in exec_module\n",
      "  File \"<frozen importlib._bootstrap>\", line 228, in _call_with_frames_removed\n",
      "  File \"/home/pita/Projects/py_fatigue/.venv/lib/python3.9/site-packages/pandas/core/arrays/__init__.py\", line 14, in <module>\n",
      "    from pandas.core.arrays.numpy_ import NumpyExtensionArray\n",
      "ImportError: cannot import name 'NumpyExtensionArray' from 'pandas.core.arrays.numpy_' (/home/pita/Projects/py_fatigue/.venv/lib/python3.9/site-packages/pandas/core/arrays/numpy_.py)\n",
      "]\n",
      "[autoreload of pandas.core.apply failed: Traceback (most recent call last):\n",
      "  File \"/home/pita/Projects/py_fatigue/.venv/lib/python3.9/site-packages/IPython/extensions/autoreload.py\", line 276, in check\n",
      "    superreload(m, reload, self.old_objects)\n",
      "  File \"/home/pita/Projects/py_fatigue/.venv/lib/python3.9/site-packages/IPython/extensions/autoreload.py\", line 475, in superreload\n",
      "    module = reload(module)\n",
      "  File \"/home/pita/.pyenv/versions/3.9.19/lib/python3.9/importlib/__init__.py\", line 169, in reload\n",
      "    _bootstrap._exec(spec, module)\n",
      "  File \"<frozen importlib._bootstrap>\", line 613, in _exec\n",
      "  File \"<frozen importlib._bootstrap_external>\", line 850, in exec_module\n",
      "  File \"<frozen importlib._bootstrap>\", line 228, in _call_with_frames_removed\n",
      "  File \"/home/pita/Projects/py_fatigue/.venv/lib/python3.9/site-packages/pandas/core/apply.py\", line 22, in <module>\n",
      "    from pandas._libs.internals import BlockValuesRefs\n",
      "ImportError: cannot import name 'BlockValuesRefs' from 'pandas._libs.internals' (/home/pita/Projects/py_fatigue/.venv/lib/python3.9/site-packages/pandas/_libs/internals.cpython-39-x86_64-linux-gnu.so)\n",
      "]\n",
      "[autoreload of pandas.core.indexes.category failed: Traceback (most recent call last):\n",
      "  File \"/home/pita/Projects/py_fatigue/.venv/lib/python3.9/site-packages/IPython/extensions/autoreload.py\", line 276, in check\n",
      "    superreload(m, reload, self.old_objects)\n",
      "  File \"/home/pita/Projects/py_fatigue/.venv/lib/python3.9/site-packages/IPython/extensions/autoreload.py\", line 500, in superreload\n",
      "    update_generic(old_obj, new_obj)\n",
      "  File \"/home/pita/Projects/py_fatigue/.venv/lib/python3.9/site-packages/IPython/extensions/autoreload.py\", line 397, in update_generic\n",
      "    update(a, b)\n",
      "  File \"/home/pita/Projects/py_fatigue/.venv/lib/python3.9/site-packages/IPython/extensions/autoreload.py\", line 349, in update_class\n",
      "    if update_generic(old_obj, new_obj):\n",
      "  File \"/home/pita/Projects/py_fatigue/.venv/lib/python3.9/site-packages/IPython/extensions/autoreload.py\", line 397, in update_generic\n",
      "    update(a, b)\n",
      "  File \"/home/pita/Projects/py_fatigue/.venv/lib/python3.9/site-packages/IPython/extensions/autoreload.py\", line 309, in update_function\n",
      "    setattr(old, name, getattr(new, name))\n",
      "ValueError: astype() requires a code object with 1 free vars, not 0\n",
      "]\n",
      "[autoreload of pandas.core.indexes.range failed: Traceback (most recent call last):\n",
      "  File \"/home/pita/Projects/py_fatigue/.venv/lib/python3.9/site-packages/IPython/extensions/autoreload.py\", line 276, in check\n",
      "    superreload(m, reload, self.old_objects)\n",
      "  File \"/home/pita/Projects/py_fatigue/.venv/lib/python3.9/site-packages/IPython/extensions/autoreload.py\", line 500, in superreload\n",
      "    update_generic(old_obj, new_obj)\n",
      "  File \"/home/pita/Projects/py_fatigue/.venv/lib/python3.9/site-packages/IPython/extensions/autoreload.py\", line 397, in update_generic\n",
      "    update(a, b)\n",
      "  File \"/home/pita/Projects/py_fatigue/.venv/lib/python3.9/site-packages/IPython/extensions/autoreload.py\", line 349, in update_class\n",
      "    if update_generic(old_obj, new_obj):\n",
      "  File \"/home/pita/Projects/py_fatigue/.venv/lib/python3.9/site-packages/IPython/extensions/autoreload.py\", line 397, in update_generic\n",
      "    update(a, b)\n",
      "  File \"/home/pita/Projects/py_fatigue/.venv/lib/python3.9/site-packages/IPython/extensions/autoreload.py\", line 309, in update_function\n",
      "    setattr(old, name, getattr(new, name))\n",
      "ValueError: get_loc() requires a code object with 1 free vars, not 0\n",
      "]\n",
      "[autoreload of pandas.core.tools.timedeltas failed: Traceback (most recent call last):\n",
      "  File \"/home/pita/Projects/py_fatigue/.venv/lib/python3.9/site-packages/IPython/extensions/autoreload.py\", line 276, in check\n",
      "    superreload(m, reload, self.old_objects)\n",
      "  File \"/home/pita/Projects/py_fatigue/.venv/lib/python3.9/site-packages/IPython/extensions/autoreload.py\", line 475, in superreload\n",
      "    module = reload(module)\n",
      "  File \"/home/pita/.pyenv/versions/3.9.19/lib/python3.9/importlib/__init__.py\", line 169, in reload\n",
      "    _bootstrap._exec(spec, module)\n",
      "  File \"<frozen importlib._bootstrap>\", line 613, in _exec\n",
      "  File \"<frozen importlib._bootstrap_external>\", line 850, in exec_module\n",
      "  File \"<frozen importlib._bootstrap>\", line 228, in _call_with_frames_removed\n",
      "  File \"/home/pita/Projects/py_fatigue/.venv/lib/python3.9/site-packages/pandas/core/tools/timedeltas.py\", line 19, in <module>\n",
      "    from pandas._libs.tslibs.timedeltas import (\n",
      "ImportError: cannot import name 'disallow_ambiguous_unit' from 'pandas._libs.tslibs.timedeltas' (/home/pita/Projects/py_fatigue/.venv/lib/python3.9/site-packages/pandas/_libs/tslibs/timedeltas.cpython-39-x86_64-linux-gnu.so)\n",
      "]\n",
      "[autoreload of pandas.core.indexes.datetimelike failed: Traceback (most recent call last):\n",
      "  File \"/home/pita/Projects/py_fatigue/.venv/lib/python3.9/site-packages/IPython/extensions/autoreload.py\", line 276, in check\n",
      "    superreload(m, reload, self.old_objects)\n",
      "  File \"/home/pita/Projects/py_fatigue/.venv/lib/python3.9/site-packages/IPython/extensions/autoreload.py\", line 475, in superreload\n",
      "    module = reload(module)\n",
      "  File \"/home/pita/.pyenv/versions/3.9.19/lib/python3.9/importlib/__init__.py\", line 169, in reload\n",
      "    _bootstrap._exec(spec, module)\n",
      "  File \"<frozen importlib._bootstrap>\", line 613, in _exec\n",
      "  File \"<frozen importlib._bootstrap_external>\", line 850, in exec_module\n",
      "  File \"<frozen importlib._bootstrap>\", line 228, in _call_with_frames_removed\n",
      "  File \"/home/pita/Projects/py_fatigue/.venv/lib/python3.9/site-packages/pandas/core/indexes/datetimelike.py\", line 35, in <module>\n",
      "    from pandas._libs.tslibs.dtypes import freq_to_period_freqstr\n",
      "ImportError: cannot import name 'freq_to_period_freqstr' from 'pandas._libs.tslibs.dtypes' (/home/pita/Projects/py_fatigue/.venv/lib/python3.9/site-packages/pandas/_libs/tslibs/dtypes.cpython-39-x86_64-linux-gnu.so)\n",
      "]\n",
      "[autoreload of pandas.core.indexes.datetimes failed: Traceback (most recent call last):\n",
      "  File \"/home/pita/Projects/py_fatigue/.venv/lib/python3.9/site-packages/IPython/extensions/autoreload.py\", line 276, in check\n",
      "    superreload(m, reload, self.old_objects)\n",
      "  File \"/home/pita/Projects/py_fatigue/.venv/lib/python3.9/site-packages/IPython/extensions/autoreload.py\", line 475, in superreload\n",
      "    module = reload(module)\n",
      "  File \"/home/pita/.pyenv/versions/3.9.19/lib/python3.9/importlib/__init__.py\", line 169, in reload\n",
      "    _bootstrap._exec(spec, module)\n",
      "  File \"<frozen importlib._bootstrap>\", line 613, in _exec\n",
      "  File \"<frozen importlib._bootstrap_external>\", line 850, in exec_module\n",
      "  File \"<frozen importlib._bootstrap>\", line 228, in _call_with_frames_removed\n",
      "  File \"/home/pita/Projects/py_fatigue/.venv/lib/python3.9/site-packages/pandas/core/indexes/datetimes.py\", line 70, in <module>\n",
      "    from pandas._libs.tslibs.dtypes import OFFSET_TO_PERIOD_FREQSTR\n",
      "ImportError: cannot import name 'OFFSET_TO_PERIOD_FREQSTR' from 'pandas._libs.tslibs.dtypes' (/home/pita/Projects/py_fatigue/.venv/lib/python3.9/site-packages/pandas/_libs/tslibs/dtypes.cpython-39-x86_64-linux-gnu.so)\n",
      "]\n",
      "[autoreload of pandas.core.indexes.multi failed: Traceback (most recent call last):\n",
      "  File \"/home/pita/Projects/py_fatigue/.venv/lib/python3.9/site-packages/IPython/extensions/autoreload.py\", line 276, in check\n",
      "    superreload(m, reload, self.old_objects)\n",
      "  File \"/home/pita/Projects/py_fatigue/.venv/lib/python3.9/site-packages/IPython/extensions/autoreload.py\", line 500, in superreload\n",
      "    update_generic(old_obj, new_obj)\n",
      "  File \"/home/pita/Projects/py_fatigue/.venv/lib/python3.9/site-packages/IPython/extensions/autoreload.py\", line 397, in update_generic\n",
      "    update(a, b)\n",
      "  File \"/home/pita/Projects/py_fatigue/.venv/lib/python3.9/site-packages/IPython/extensions/autoreload.py\", line 349, in update_class\n",
      "    if update_generic(old_obj, new_obj):\n",
      "  File \"/home/pita/Projects/py_fatigue/.venv/lib/python3.9/site-packages/IPython/extensions/autoreload.py\", line 397, in update_generic\n",
      "    update(a, b)\n",
      "  File \"/home/pita/Projects/py_fatigue/.venv/lib/python3.9/site-packages/IPython/extensions/autoreload.py\", line 309, in update_function\n",
      "    setattr(old, name, getattr(new, name))\n",
      "ValueError: set_levels() requires a code object with 4 free vars, not 0\n",
      "]\n",
      "[autoreload of pandas.core.indexes.timedeltas failed: Traceback (most recent call last):\n",
      "  File \"/home/pita/Projects/py_fatigue/.venv/lib/python3.9/site-packages/IPython/extensions/autoreload.py\", line 276, in check\n",
      "    superreload(m, reload, self.old_objects)\n",
      "  File \"/home/pita/Projects/py_fatigue/.venv/lib/python3.9/site-packages/IPython/extensions/autoreload.py\", line 475, in superreload\n",
      "    module = reload(module)\n",
      "  File \"/home/pita/.pyenv/versions/3.9.19/lib/python3.9/importlib/__init__.py\", line 169, in reload\n",
      "    _bootstrap._exec(spec, module)\n",
      "  File \"<frozen importlib._bootstrap>\", line 613, in _exec\n",
      "  File \"<frozen importlib._bootstrap_external>\", line 850, in exec_module\n",
      "  File \"<frozen importlib._bootstrap>\", line 228, in _call_with_frames_removed\n",
      "  File \"/home/pita/Projects/py_fatigue/.venv/lib/python3.9/site-packages/pandas/core/indexes/timedeltas.py\", line 16, in <module>\n",
      "    from pandas._libs.tslibs.timedeltas import disallow_ambiguous_unit\n",
      "ImportError: cannot import name 'disallow_ambiguous_unit' from 'pandas._libs.tslibs.timedeltas' (/home/pita/Projects/py_fatigue/.venv/lib/python3.9/site-packages/pandas/_libs/tslibs/timedeltas.cpython-39-x86_64-linux-gnu.so)\n",
      "]\n",
      "[autoreload of pandas.core.indexes.interval failed: Traceback (most recent call last):\n",
      "  File \"/home/pita/Projects/py_fatigue/.venv/lib/python3.9/site-packages/IPython/extensions/autoreload.py\", line 276, in check\n",
      "    superreload(m, reload, self.old_objects)\n",
      "  File \"/home/pita/Projects/py_fatigue/.venv/lib/python3.9/site-packages/IPython/extensions/autoreload.py\", line 475, in superreload\n",
      "    module = reload(module)\n",
      "  File \"/home/pita/.pyenv/versions/3.9.19/lib/python3.9/importlib/__init__.py\", line 169, in reload\n",
      "    _bootstrap._exec(spec, module)\n",
      "  File \"<frozen importlib._bootstrap>\", line 613, in _exec\n",
      "  File \"<frozen importlib._bootstrap_external>\", line 850, in exec_module\n",
      "  File \"<frozen importlib._bootstrap>\", line 228, in _call_with_frames_removed\n",
      "  File \"/home/pita/Projects/py_fatigue/.venv/lib/python3.9/site-packages/pandas/core/indexes/interval.py\", line 37, in <module>\n",
      "    from pandas.core.dtypes.cast import (\n",
      "ImportError: cannot import name 'maybe_upcast_numeric_to_64bit' from 'pandas.core.dtypes.cast' (/home/pita/Projects/py_fatigue/.venv/lib/python3.9/site-packages/pandas/core/dtypes/cast.py)\n",
      "]\n",
      "[autoreload of pandas.core.indexes.period failed: Traceback (most recent call last):\n",
      "  File \"/home/pita/Projects/py_fatigue/.venv/lib/python3.9/site-packages/IPython/extensions/autoreload.py\", line 276, in check\n",
      "    superreload(m, reload, self.old_objects)\n",
      "  File \"/home/pita/Projects/py_fatigue/.venv/lib/python3.9/site-packages/IPython/extensions/autoreload.py\", line 475, in superreload\n",
      "    module = reload(module)\n",
      "  File \"/home/pita/.pyenv/versions/3.9.19/lib/python3.9/importlib/__init__.py\", line 169, in reload\n",
      "    _bootstrap._exec(spec, module)\n",
      "  File \"<frozen importlib._bootstrap>\", line 613, in _exec\n",
      "  File \"<frozen importlib._bootstrap_external>\", line 850, in exec_module\n",
      "  File \"<frozen importlib._bootstrap>\", line 228, in _call_with_frames_removed\n",
      "  File \"/home/pita/Projects/py_fatigue/.venv/lib/python3.9/site-packages/pandas/core/indexes/period.py\", line 20, in <module>\n",
      "    from pandas._libs.tslibs.dtypes import OFFSET_TO_PERIOD_FREQSTR\n",
      "ImportError: cannot import name 'OFFSET_TO_PERIOD_FREQSTR' from 'pandas._libs.tslibs.dtypes' (/home/pita/Projects/py_fatigue/.venv/lib/python3.9/site-packages/pandas/_libs/tslibs/dtypes.cpython-39-x86_64-linux-gnu.so)\n",
      "]\n",
      "[autoreload of pandas.core.internals.blocks failed: Traceback (most recent call last):\n",
      "  File \"/home/pita/Projects/py_fatigue/.venv/lib/python3.9/site-packages/IPython/extensions/autoreload.py\", line 276, in check\n",
      "    superreload(m, reload, self.old_objects)\n",
      "  File \"/home/pita/Projects/py_fatigue/.venv/lib/python3.9/site-packages/IPython/extensions/autoreload.py\", line 475, in superreload\n",
      "    module = reload(module)\n",
      "  File \"/home/pita/.pyenv/versions/3.9.19/lib/python3.9/importlib/__init__.py\", line 169, in reload\n",
      "    _bootstrap._exec(spec, module)\n",
      "  File \"<frozen importlib._bootstrap>\", line 613, in _exec\n",
      "  File \"<frozen importlib._bootstrap_external>\", line 850, in exec_module\n",
      "  File \"<frozen importlib._bootstrap>\", line 228, in _call_with_frames_removed\n",
      "  File \"/home/pita/Projects/py_fatigue/.venv/lib/python3.9/site-packages/pandas/core/internals/blocks.py\", line 30, in <module>\n",
      "    from pandas._libs.internals import (\n",
      "ImportError: cannot import name 'BlockValuesRefs' from 'pandas._libs.internals' (/home/pita/Projects/py_fatigue/.venv/lib/python3.9/site-packages/pandas/_libs/internals.cpython-39-x86_64-linux-gnu.so)\n",
      "]\n",
      "[autoreload of pandas.core.internals.base failed: Traceback (most recent call last):\n",
      "  File \"/home/pita/Projects/py_fatigue/.venv/lib/python3.9/site-packages/IPython/extensions/autoreload.py\", line 276, in check\n",
      "    superreload(m, reload, self.old_objects)\n",
      "  File \"/home/pita/Projects/py_fatigue/.venv/lib/python3.9/site-packages/IPython/extensions/autoreload.py\", line 475, in superreload\n",
      "    module = reload(module)\n",
      "  File \"/home/pita/.pyenv/versions/3.9.19/lib/python3.9/importlib/__init__.py\", line 169, in reload\n",
      "    _bootstrap._exec(spec, module)\n",
      "  File \"<frozen importlib._bootstrap>\", line 613, in _exec\n",
      "  File \"<frozen importlib._bootstrap_external>\", line 850, in exec_module\n",
      "  File \"<frozen importlib._bootstrap>\", line 228, in _call_with_frames_removed\n",
      "  File \"/home/pita/Projects/py_fatigue/.venv/lib/python3.9/site-packages/pandas/core/internals/base.py\", line 33, in <module>\n",
      "    from pandas.core.dtypes.dtypes import (\n",
      "ImportError: cannot import name 'SparseDtype' from 'pandas.core.dtypes.dtypes' (/home/pita/Projects/py_fatigue/.venv/lib/python3.9/site-packages/pandas/core/dtypes/dtypes.py)\n",
      "]\n",
      "[autoreload of pandas.core.internals.array_manager failed: Traceback (most recent call last):\n",
      "  File \"/home/pita/Projects/py_fatigue/.venv/lib/python3.9/site-packages/IPython/extensions/autoreload.py\", line 276, in check\n",
      "    superreload(m, reload, self.old_objects)\n",
      "  File \"/home/pita/Projects/py_fatigue/.venv/lib/python3.9/site-packages/IPython/extensions/autoreload.py\", line 475, in superreload\n",
      "    module = reload(module)\n",
      "  File \"/home/pita/.pyenv/versions/3.9.19/lib/python3.9/importlib/__init__.py\", line 169, in reload\n",
      "    _bootstrap._exec(spec, module)\n",
      "  File \"<frozen importlib._bootstrap>\", line 613, in _exec\n",
      "  File \"<frozen importlib._bootstrap_external>\", line 850, in exec_module\n",
      "  File \"<frozen importlib._bootstrap>\", line 228, in _call_with_frames_removed\n",
      "  File \"/home/pita/Projects/py_fatigue/.venv/lib/python3.9/site-packages/pandas/core/internals/array_manager.py\", line 24, in <module>\n",
      "    from pandas.core.dtypes.cast import (\n",
      "ImportError: cannot import name 'np_find_common_type' from 'pandas.core.dtypes.cast' (/home/pita/Projects/py_fatigue/.venv/lib/python3.9/site-packages/pandas/core/dtypes/cast.py)\n",
      "]\n",
      "[autoreload of pandas.core.internals.managers failed: Traceback (most recent call last):\n",
      "  File \"/home/pita/Projects/py_fatigue/.venv/lib/python3.9/site-packages/IPython/extensions/autoreload.py\", line 276, in check\n",
      "    superreload(m, reload, self.old_objects)\n",
      "  File \"/home/pita/Projects/py_fatigue/.venv/lib/python3.9/site-packages/IPython/extensions/autoreload.py\", line 475, in superreload\n",
      "    module = reload(module)\n",
      "  File \"/home/pita/.pyenv/versions/3.9.19/lib/python3.9/importlib/__init__.py\", line 169, in reload\n",
      "    _bootstrap._exec(spec, module)\n",
      "  File \"<frozen importlib._bootstrap>\", line 613, in _exec\n",
      "  File \"<frozen importlib._bootstrap_external>\", line 850, in exec_module\n",
      "  File \"<frozen importlib._bootstrap>\", line 228, in _call_with_frames_removed\n",
      "  File \"/home/pita/Projects/py_fatigue/.venv/lib/python3.9/site-packages/pandas/core/internals/managers.py\", line 27, in <module>\n",
      "    from pandas._libs.internals import (\n",
      "ImportError: cannot import name 'BlockValuesRefs' from 'pandas._libs.internals' (/home/pita/Projects/py_fatigue/.venv/lib/python3.9/site-packages/pandas/_libs/internals.cpython-39-x86_64-linux-gnu.so)\n",
      "]\n",
      "[autoreload of pandas.core.internals.concat failed: Traceback (most recent call last):\n",
      "  File \"/home/pita/Projects/py_fatigue/.venv/lib/python3.9/site-packages/IPython/extensions/autoreload.py\", line 276, in check\n",
      "    superreload(m, reload, self.old_objects)\n",
      "  File \"/home/pita/Projects/py_fatigue/.venv/lib/python3.9/site-packages/IPython/extensions/autoreload.py\", line 475, in superreload\n",
      "    module = reload(module)\n",
      "  File \"/home/pita/.pyenv/versions/3.9.19/lib/python3.9/importlib/__init__.py\", line 169, in reload\n",
      "    _bootstrap._exec(spec, module)\n",
      "  File \"<frozen importlib._bootstrap>\", line 613, in _exec\n",
      "  File \"<frozen importlib._bootstrap_external>\", line 850, in exec_module\n",
      "  File \"<frozen importlib._bootstrap>\", line 228, in _call_with_frames_removed\n",
      "  File \"/home/pita/Projects/py_fatigue/.venv/lib/python3.9/site-packages/pandas/core/internals/concat.py\", line 31, in <module>\n",
      "    from pandas.core.dtypes.dtypes import (\n",
      "ImportError: cannot import name 'SparseDtype' from 'pandas.core.dtypes.dtypes' (/home/pita/Projects/py_fatigue/.venv/lib/python3.9/site-packages/pandas/core/dtypes/dtypes.py)\n",
      "]\n",
      "[autoreload of pandas.core.reshape.concat failed: Traceback (most recent call last):\n",
      "  File \"/home/pita/Projects/py_fatigue/.venv/lib/python3.9/site-packages/IPython/extensions/autoreload.py\", line 276, in check\n",
      "    superreload(m, reload, self.old_objects)\n",
      "  File \"/home/pita/Projects/py_fatigue/.venv/lib/python3.9/site-packages/IPython/extensions/autoreload.py\", line 500, in superreload\n",
      "    update_generic(old_obj, new_obj)\n",
      "  File \"/home/pita/Projects/py_fatigue/.venv/lib/python3.9/site-packages/IPython/extensions/autoreload.py\", line 397, in update_generic\n",
      "    update(a, b)\n",
      "  File \"/home/pita/Projects/py_fatigue/.venv/lib/python3.9/site-packages/IPython/extensions/autoreload.py\", line 309, in update_function\n",
      "    setattr(old, name, getattr(new, name))\n",
      "ValueError: concat() requires a code object with 4 free vars, not 0\n",
      "]\n",
      "[autoreload of pandas.io.formats.format failed: Traceback (most recent call last):\n",
      "  File \"/home/pita/Projects/py_fatigue/.venv/lib/python3.9/site-packages/IPython/extensions/autoreload.py\", line 276, in check\n",
      "    superreload(m, reload, self.old_objects)\n",
      "  File \"/home/pita/Projects/py_fatigue/.venv/lib/python3.9/site-packages/IPython/extensions/autoreload.py\", line 500, in superreload\n",
      "    update_generic(old_obj, new_obj)\n",
      "  File \"/home/pita/Projects/py_fatigue/.venv/lib/python3.9/site-packages/IPython/extensions/autoreload.py\", line 397, in update_generic\n",
      "    update(a, b)\n",
      "  File \"/home/pita/Projects/py_fatigue/.venv/lib/python3.9/site-packages/IPython/extensions/autoreload.py\", line 349, in update_class\n",
      "    if update_generic(old_obj, new_obj):\n",
      "  File \"/home/pita/Projects/py_fatigue/.venv/lib/python3.9/site-packages/IPython/extensions/autoreload.py\", line 397, in update_generic\n",
      "    update(a, b)\n",
      "  File \"/home/pita/Projects/py_fatigue/.venv/lib/python3.9/site-packages/IPython/extensions/autoreload.py\", line 309, in update_function\n",
      "    setattr(old, name, getattr(new, name))\n",
      "ValueError: to_csv() requires a code object with 5 free vars, not 0\n",
      "]\n",
      "[autoreload of pandas.core.internals.construction failed: Traceback (most recent call last):\n",
      "  File \"/home/pita/Projects/py_fatigue/.venv/lib/python3.9/site-packages/IPython/extensions/autoreload.py\", line 276, in check\n",
      "    superreload(m, reload, self.old_objects)\n",
      "  File \"/home/pita/Projects/py_fatigue/.venv/lib/python3.9/site-packages/IPython/extensions/autoreload.py\", line 475, in superreload\n",
      "    module = reload(module)\n",
      "  File \"/home/pita/.pyenv/versions/3.9.19/lib/python3.9/importlib/__init__.py\", line 169, in reload\n",
      "    _bootstrap._exec(spec, module)\n",
      "  File \"<frozen importlib._bootstrap>\", line 613, in _exec\n",
      "  File \"<frozen importlib._bootstrap_external>\", line 850, in exec_module\n",
      "  File \"<frozen importlib._bootstrap>\", line 228, in _call_with_frames_removed\n",
      "  File \"/home/pita/Projects/py_fatigue/.venv/lib/python3.9/site-packages/pandas/core/internals/construction.py\", line 20, in <module>\n",
      "    from pandas.core.dtypes.astype import astype_is_view\n",
      "ImportError: cannot import name 'astype_is_view' from 'pandas.core.dtypes.astype' (/home/pita/Projects/py_fatigue/.venv/lib/python3.9/site-packages/pandas/core/dtypes/astype.py)\n",
      "]\n",
      "[autoreload of pandas.core.window.rolling failed: Traceback (most recent call last):\n",
      "  File \"/home/pita/Projects/py_fatigue/.venv/lib/python3.9/site-packages/IPython/extensions/autoreload.py\", line 276, in check\n",
      "    superreload(m, reload, self.old_objects)\n",
      "  File \"/home/pita/Projects/py_fatigue/.venv/lib/python3.9/site-packages/IPython/extensions/autoreload.py\", line 475, in superreload\n",
      "    module = reload(module)\n",
      "  File \"/home/pita/.pyenv/versions/3.9.19/lib/python3.9/importlib/__init__.py\", line 169, in reload\n",
      "    _bootstrap._exec(spec, module)\n",
      "  File \"<frozen importlib._bootstrap>\", line 613, in _exec\n",
      "  File \"<frozen importlib._bootstrap_external>\", line 850, in exec_module\n",
      "  File \"<frozen importlib._bootstrap>\", line 228, in _call_with_frames_removed\n",
      "  File \"/home/pita/Projects/py_fatigue/.venv/lib/python3.9/site-packages/pandas/core/window/rolling.py\", line 41, in <module>\n",
      "    from pandas.core.dtypes.dtypes import ArrowDtype\n",
      "ImportError: cannot import name 'ArrowDtype' from 'pandas.core.dtypes.dtypes' (/home/pita/Projects/py_fatigue/.venv/lib/python3.9/site-packages/pandas/core/dtypes/dtypes.py)\n",
      "]\n",
      "[autoreload of pandas.core.window.expanding failed: Traceback (most recent call last):\n",
      "  File \"/home/pita/Projects/py_fatigue/.venv/lib/python3.9/site-packages/IPython/extensions/autoreload.py\", line 276, in check\n",
      "    superreload(m, reload, self.old_objects)\n",
      "  File \"/home/pita/Projects/py_fatigue/.venv/lib/python3.9/site-packages/IPython/extensions/autoreload.py\", line 500, in superreload\n",
      "    update_generic(old_obj, new_obj)\n",
      "  File \"/home/pita/Projects/py_fatigue/.venv/lib/python3.9/site-packages/IPython/extensions/autoreload.py\", line 397, in update_generic\n",
      "    update(a, b)\n",
      "  File \"/home/pita/Projects/py_fatigue/.venv/lib/python3.9/site-packages/IPython/extensions/autoreload.py\", line 349, in update_class\n",
      "    if update_generic(old_obj, new_obj):\n",
      "  File \"/home/pita/Projects/py_fatigue/.venv/lib/python3.9/site-packages/IPython/extensions/autoreload.py\", line 397, in update_generic\n",
      "    update(a, b)\n",
      "  File \"/home/pita/Projects/py_fatigue/.venv/lib/python3.9/site-packages/IPython/extensions/autoreload.py\", line 309, in update_function\n",
      "    setattr(old, name, getattr(new, name))\n",
      "ValueError: quantile() requires a code object with 1 free vars, not 5\n",
      "]\n",
      "[autoreload of pandas.core.generic failed: Traceback (most recent call last):\n",
      "  File \"/home/pita/Projects/py_fatigue/.venv/lib/python3.9/site-packages/IPython/extensions/autoreload.py\", line 276, in check\n",
      "    superreload(m, reload, self.old_objects)\n",
      "  File \"/home/pita/Projects/py_fatigue/.venv/lib/python3.9/site-packages/IPython/extensions/autoreload.py\", line 475, in superreload\n",
      "    module = reload(module)\n",
      "  File \"/home/pita/.pyenv/versions/3.9.19/lib/python3.9/importlib/__init__.py\", line 169, in reload\n",
      "    _bootstrap._exec(spec, module)\n",
      "  File \"<frozen importlib._bootstrap>\", line 613, in _exec\n",
      "  File \"<frozen importlib._bootstrap_external>\", line 850, in exec_module\n",
      "  File \"<frozen importlib._bootstrap>\", line 228, in _call_with_frames_removed\n",
      "  File \"/home/pita/Projects/py_fatigue/.venv/lib/python3.9/site-packages/pandas/core/generic.py\", line 37, in <module>\n",
      "    from pandas._libs.lib import is_range_indexer\n",
      "ImportError: cannot import name 'is_range_indexer' from 'pandas._libs.lib' (/home/pita/Projects/py_fatigue/.venv/lib/python3.9/site-packages/pandas/_libs/lib.cpython-39-x86_64-linux-gnu.so)\n",
      "]\n",
      "[autoreload of pandas.core.tools.numeric failed: Traceback (most recent call last):\n",
      "  File \"/home/pita/Projects/py_fatigue/.venv/lib/python3.9/site-packages/IPython/extensions/autoreload.py\", line 276, in check\n",
      "    superreload(m, reload, self.old_objects)\n",
      "  File \"/home/pita/Projects/py_fatigue/.venv/lib/python3.9/site-packages/IPython/extensions/autoreload.py\", line 475, in superreload\n",
      "    module = reload(module)\n",
      "  File \"/home/pita/.pyenv/versions/3.9.19/lib/python3.9/importlib/__init__.py\", line 169, in reload\n",
      "    _bootstrap._exec(spec, module)\n",
      "  File \"<frozen importlib._bootstrap>\", line 613, in _exec\n",
      "  File \"<frozen importlib._bootstrap_external>\", line 850, in exec_module\n",
      "  File \"<frozen importlib._bootstrap>\", line 228, in _call_with_frames_removed\n",
      "  File \"/home/pita/Projects/py_fatigue/.venv/lib/python3.9/site-packages/pandas/core/tools/numeric.py\", line 27, in <module>\n",
      "    from pandas.core.dtypes.dtypes import ArrowDtype\n",
      "ImportError: cannot import name 'ArrowDtype' from 'pandas.core.dtypes.dtypes' (/home/pita/Projects/py_fatigue/.venv/lib/python3.9/site-packages/pandas/core/dtypes/dtypes.py)\n",
      "]\n",
      "[autoreload of pandas.core.reshape.melt failed: Traceback (most recent call last):\n",
      "  File \"/home/pita/Projects/py_fatigue/.venv/lib/python3.9/site-packages/IPython/extensions/autoreload.py\", line 276, in check\n",
      "    superreload(m, reload, self.old_objects)\n",
      "  File \"/home/pita/Projects/py_fatigue/.venv/lib/python3.9/site-packages/IPython/extensions/autoreload.py\", line 500, in superreload\n",
      "    update_generic(old_obj, new_obj)\n",
      "  File \"/home/pita/Projects/py_fatigue/.venv/lib/python3.9/site-packages/IPython/extensions/autoreload.py\", line 397, in update_generic\n",
      "    update(a, b)\n",
      "  File \"/home/pita/Projects/py_fatigue/.venv/lib/python3.9/site-packages/IPython/extensions/autoreload.py\", line 309, in update_function\n",
      "    setattr(old, name, getattr(new, name))\n",
      "ValueError: lreshape() requires a code object with 5 free vars, not 0\n",
      "]\n",
      "[autoreload of pandas.core.indexes.accessors failed: Traceback (most recent call last):\n",
      "  File \"/home/pita/Projects/py_fatigue/.venv/lib/python3.9/site-packages/IPython/extensions/autoreload.py\", line 276, in check\n",
      "    superreload(m, reload, self.old_objects)\n",
      "  File \"/home/pita/Projects/py_fatigue/.venv/lib/python3.9/site-packages/IPython/extensions/autoreload.py\", line 475, in superreload\n",
      "    module = reload(module)\n",
      "  File \"/home/pita/.pyenv/versions/3.9.19/lib/python3.9/importlib/__init__.py\", line 169, in reload\n",
      "    _bootstrap._exec(spec, module)\n",
      "  File \"<frozen importlib._bootstrap>\", line 613, in _exec\n",
      "  File \"<frozen importlib._bootstrap_external>\", line 850, in exec_module\n",
      "  File \"<frozen importlib._bootstrap>\", line 228, in _call_with_frames_removed\n",
      "  File \"/home/pita/Projects/py_fatigue/.venv/lib/python3.9/site-packages/pandas/core/indexes/accessors.py\", line 21, in <module>\n",
      "    from pandas.core.dtypes.dtypes import (\n",
      "ImportError: cannot import name 'ArrowDtype' from 'pandas.core.dtypes.dtypes' (/home/pita/Projects/py_fatigue/.venv/lib/python3.9/site-packages/pandas/core/dtypes/dtypes.py)\n",
      "]\n",
      "[autoreload of pandas.arrays failed: Traceback (most recent call last):\n",
      "  File \"/home/pita/Projects/py_fatigue/.venv/lib/python3.9/site-packages/IPython/extensions/autoreload.py\", line 276, in check\n",
      "    superreload(m, reload, self.old_objects)\n",
      "  File \"/home/pita/Projects/py_fatigue/.venv/lib/python3.9/site-packages/IPython/extensions/autoreload.py\", line 475, in superreload\n",
      "    module = reload(module)\n",
      "  File \"/home/pita/.pyenv/versions/3.9.19/lib/python3.9/importlib/__init__.py\", line 169, in reload\n",
      "    _bootstrap._exec(spec, module)\n",
      "  File \"<frozen importlib._bootstrap>\", line 613, in _exec\n",
      "  File \"<frozen importlib._bootstrap_external>\", line 850, in exec_module\n",
      "  File \"<frozen importlib._bootstrap>\", line 228, in _call_with_frames_removed\n",
      "  File \"/home/pita/Projects/py_fatigue/.venv/lib/python3.9/site-packages/pandas/arrays/__init__.py\", line 6, in <module>\n",
      "    from pandas.core.arrays import (\n",
      "ImportError: cannot import name 'NumpyExtensionArray' from 'pandas.core.arrays' (/home/pita/Projects/py_fatigue/.venv/lib/python3.9/site-packages/pandas/core/arrays/__init__.py)\n",
      "]\n",
      "[autoreload of pandas.core.tools.datetimes failed: Traceback (most recent call last):\n",
      "  File \"/home/pita/Projects/py_fatigue/.venv/lib/python3.9/site-packages/IPython/extensions/autoreload.py\", line 276, in check\n",
      "    superreload(m, reload, self.old_objects)\n",
      "  File \"/home/pita/Projects/py_fatigue/.venv/lib/python3.9/site-packages/IPython/extensions/autoreload.py\", line 475, in superreload\n",
      "    module = reload(module)\n",
      "  File \"/home/pita/.pyenv/versions/3.9.19/lib/python3.9/importlib/__init__.py\", line 169, in reload\n",
      "    _bootstrap._exec(spec, module)\n",
      "  File \"<frozen importlib._bootstrap>\", line 613, in _exec\n",
      "  File \"<frozen importlib._bootstrap_external>\", line 850, in exec_module\n",
      "  File \"<frozen importlib._bootstrap>\", line 228, in _call_with_frames_removed\n",
      "  File \"/home/pita/Projects/py_fatigue/.venv/lib/python3.9/site-packages/pandas/core/tools/datetimes.py\", line 23, in <module>\n",
      "    from pandas._libs.tslibs import (\n",
      "ImportError: cannot import name 'is_supported_dtype' from 'pandas._libs.tslibs' (/home/pita/Projects/py_fatigue/.venv/lib/python3.9/site-packages/pandas/_libs/tslibs/__init__.py)\n",
      "]\n",
      "[autoreload of pandas.core.series failed: Traceback (most recent call last):\n",
      "  File \"/home/pita/Projects/py_fatigue/.venv/lib/python3.9/site-packages/IPython/extensions/autoreload.py\", line 276, in check\n",
      "    superreload(m, reload, self.old_objects)\n",
      "  File \"/home/pita/Projects/py_fatigue/.venv/lib/python3.9/site-packages/IPython/extensions/autoreload.py\", line 475, in superreload\n",
      "    module = reload(module)\n",
      "  File \"/home/pita/.pyenv/versions/3.9.19/lib/python3.9/importlib/__init__.py\", line 169, in reload\n",
      "    _bootstrap._exec(spec, module)\n",
      "  File \"<frozen importlib._bootstrap>\", line 613, in _exec\n",
      "  File \"<frozen importlib._bootstrap_external>\", line 850, in exec_module\n",
      "  File \"<frozen importlib._bootstrap>\", line 228, in _call_with_frames_removed\n",
      "  File \"/home/pita/Projects/py_fatigue/.venv/lib/python3.9/site-packages/pandas/core/series.py\", line 40, in <module>\n",
      "    from pandas._libs.lib import is_range_indexer\n",
      "ImportError: cannot import name 'is_range_indexer' from 'pandas._libs.lib' (/home/pita/Projects/py_fatigue/.venv/lib/python3.9/site-packages/pandas/_libs/lib.cpython-39-x86_64-linux-gnu.so)\n",
      "]\n",
      "[autoreload of pandas.core.frame failed: Traceback (most recent call last):\n",
      "  File \"/home/pita/Projects/py_fatigue/.venv/lib/python3.9/site-packages/IPython/extensions/autoreload.py\", line 276, in check\n",
      "    superreload(m, reload, self.old_objects)\n",
      "  File \"/home/pita/Projects/py_fatigue/.venv/lib/python3.9/site-packages/IPython/extensions/autoreload.py\", line 475, in superreload\n",
      "    module = reload(module)\n",
      "  File \"/home/pita/.pyenv/versions/3.9.19/lib/python3.9/importlib/__init__.py\", line 169, in reload\n",
      "    _bootstrap._exec(spec, module)\n",
      "  File \"<frozen importlib._bootstrap>\", line 613, in _exec\n",
      "  File \"<frozen importlib._bootstrap_external>\", line 850, in exec_module\n",
      "  File \"<frozen importlib._bootstrap>\", line 228, in _call_with_frames_removed\n",
      "  File \"/home/pita/Projects/py_fatigue/.venv/lib/python3.9/site-packages/pandas/core/frame.py\", line 55, in <module>\n",
      "    from pandas._libs.lib import is_range_indexer\n",
      "ImportError: cannot import name 'is_range_indexer' from 'pandas._libs.lib' (/home/pita/Projects/py_fatigue/.venv/lib/python3.9/site-packages/pandas/_libs/lib.cpython-39-x86_64-linux-gnu.so)\n",
      "]\n",
      "[autoreload of pandas.core.groupby.ops failed: Traceback (most recent call last):\n",
      "  File \"/home/pita/Projects/py_fatigue/.venv/lib/python3.9/site-packages/IPython/extensions/autoreload.py\", line 276, in check\n",
      "    superreload(m, reload, self.old_objects)\n",
      "  File \"/home/pita/Projects/py_fatigue/.venv/lib/python3.9/site-packages/IPython/extensions/autoreload.py\", line 475, in superreload\n",
      "    module = reload(module)\n",
      "  File \"/home/pita/.pyenv/versions/3.9.19/lib/python3.9/importlib/__init__.py\", line 169, in reload\n",
      "    _bootstrap._exec(spec, module)\n",
      "  File \"<frozen importlib._bootstrap>\", line 613, in _exec\n",
      "  File \"<frozen importlib._bootstrap_external>\", line 850, in exec_module\n",
      "  File \"<frozen importlib._bootstrap>\", line 228, in _call_with_frames_removed\n",
      "  File \"/home/pita/Projects/py_fatigue/.venv/lib/python3.9/site-packages/pandas/core/groupby/ops.py\", line 105, in <module>\n",
      "    class WrappedCythonOp:\n",
      "  File \"/home/pita/Projects/py_fatigue/.venv/lib/python3.9/site-packages/pandas/core/groupby/ops.py\", line 136, in WrappedCythonOp\n",
      "    \"idxmin\": functools.partial(libgroupby.group_idxmin_idxmax, name=\"idxmin\"),\n",
      "AttributeError: module 'pandas._libs.groupby' has no attribute 'group_idxmin_idxmax'\n",
      "]\n",
      "[autoreload of pandas.core.groupby.groupby failed: Traceback (most recent call last):\n",
      "  File \"/home/pita/Projects/py_fatigue/.venv/lib/python3.9/site-packages/IPython/extensions/autoreload.py\", line 276, in check\n",
      "    superreload(m, reload, self.old_objects)\n",
      "  File \"/home/pita/Projects/py_fatigue/.venv/lib/python3.9/site-packages/IPython/extensions/autoreload.py\", line 475, in superreload\n",
      "    module = reload(module)\n",
      "  File \"/home/pita/.pyenv/versions/3.9.19/lib/python3.9/importlib/__init__.py\", line 169, in reload\n",
      "    _bootstrap._exec(spec, module)\n",
      "  File \"<frozen importlib._bootstrap>\", line 613, in _exec\n",
      "  File \"<frozen importlib._bootstrap_external>\", line 850, in exec_module\n",
      "  File \"<frozen importlib._bootstrap>\", line 228, in _call_with_frames_removed\n",
      "  File \"/home/pita/Projects/py_fatigue/.venv/lib/python3.9/site-packages/pandas/core/groupby/groupby.py\", line 102, in <module>\n",
      "    from pandas.core.apply import warn_alias_replacement\n",
      "ImportError: cannot import name 'warn_alias_replacement' from 'pandas.core.apply' (/home/pita/Projects/py_fatigue/.venv/lib/python3.9/site-packages/pandas/core/apply.py)\n",
      "]\n",
      "[autoreload of pandas.core.groupby.generic failed: Traceback (most recent call last):\n",
      "  File \"/home/pita/Projects/py_fatigue/.venv/lib/python3.9/site-packages/IPython/extensions/autoreload.py\", line 276, in check\n",
      "    superreload(m, reload, self.old_objects)\n",
      "  File \"/home/pita/Projects/py_fatigue/.venv/lib/python3.9/site-packages/IPython/extensions/autoreload.py\", line 475, in superreload\n",
      "    module = reload(module)\n",
      "  File \"/home/pita/.pyenv/versions/3.9.19/lib/python3.9/importlib/__init__.py\", line 169, in reload\n",
      "    _bootstrap._exec(spec, module)\n",
      "  File \"<frozen importlib._bootstrap>\", line 613, in _exec\n",
      "  File \"<frozen importlib._bootstrap_external>\", line 850, in exec_module\n",
      "  File \"<frozen importlib._bootstrap>\", line 228, in _call_with_frames_removed\n",
      "  File \"/home/pita/Projects/py_fatigue/.venv/lib/python3.9/site-packages/pandas/core/groupby/generic.py\", line 60, in <module>\n",
      "    from pandas.core.apply import (\n",
      "ImportError: cannot import name 'warn_alias_replacement' from 'pandas.core.apply' (/home/pita/Projects/py_fatigue/.venv/lib/python3.9/site-packages/pandas/core/apply.py)\n",
      "]\n",
      "[autoreload of pandas.core.api failed: Traceback (most recent call last):\n",
      "  File \"/home/pita/Projects/py_fatigue/.venv/lib/python3.9/site-packages/IPython/extensions/autoreload.py\", line 276, in check\n",
      "    superreload(m, reload, self.old_objects)\n",
      "  File \"/home/pita/Projects/py_fatigue/.venv/lib/python3.9/site-packages/IPython/extensions/autoreload.py\", line 475, in superreload\n",
      "    module = reload(module)\n",
      "  File \"/home/pita/.pyenv/versions/3.9.19/lib/python3.9/importlib/__init__.py\", line 169, in reload\n",
      "    _bootstrap._exec(spec, module)\n",
      "  File \"<frozen importlib._bootstrap>\", line 613, in _exec\n",
      "  File \"<frozen importlib._bootstrap_external>\", line 850, in exec_module\n",
      "  File \"<frozen importlib._bootstrap>\", line 228, in _call_with_frames_removed\n",
      "  File \"/home/pita/Projects/py_fatigue/.venv/lib/python3.9/site-packages/pandas/core/api.py\", line 9, in <module>\n",
      "    from pandas.core.dtypes.dtypes import (\n",
      "ImportError: cannot import name 'ArrowDtype' from 'pandas.core.dtypes.dtypes' (/home/pita/Projects/py_fatigue/.venv/lib/python3.9/site-packages/pandas/core/dtypes/dtypes.py)\n",
      "]\n",
      "[autoreload of pandas.core.computation.ops failed: Traceback (most recent call last):\n",
      "  File \"/home/pita/Projects/py_fatigue/.venv/lib/python3.9/site-packages/IPython/extensions/autoreload.py\", line 276, in check\n",
      "    superreload(m, reload, self.old_objects)\n",
      "  File \"/home/pita/Projects/py_fatigue/.venv/lib/python3.9/site-packages/IPython/extensions/autoreload.py\", line 500, in superreload\n",
      "    update_generic(old_obj, new_obj)\n",
      "  File \"/home/pita/Projects/py_fatigue/.venv/lib/python3.9/site-packages/IPython/extensions/autoreload.py\", line 397, in update_generic\n",
      "    update(a, b)\n",
      "  File \"/home/pita/Projects/py_fatigue/.venv/lib/python3.9/site-packages/IPython/extensions/autoreload.py\", line 349, in update_class\n",
      "    if update_generic(old_obj, new_obj):\n",
      "  File \"/home/pita/Projects/py_fatigue/.venv/lib/python3.9/site-packages/IPython/extensions/autoreload.py\", line 397, in update_generic\n",
      "    update(a, b)\n",
      "  File \"/home/pita/Projects/py_fatigue/.venv/lib/python3.9/site-packages/IPython/extensions/autoreload.py\", line 309, in update_function\n",
      "    setattr(old, name, getattr(new, name))\n",
      "ValueError: __init__() requires a code object with 1 free vars, not 0\n",
      "]\n",
      "[autoreload of pandas.core.computation.expr failed: Traceback (most recent call last):\n",
      "  File \"/home/pita/Projects/py_fatigue/.venv/lib/python3.9/site-packages/IPython/extensions/autoreload.py\", line 276, in check\n",
      "    superreload(m, reload, self.old_objects)\n",
      "  File \"/home/pita/Projects/py_fatigue/.venv/lib/python3.9/site-packages/IPython/extensions/autoreload.py\", line 500, in superreload\n",
      "    update_generic(old_obj, new_obj)\n",
      "  File \"/home/pita/Projects/py_fatigue/.venv/lib/python3.9/site-packages/IPython/extensions/autoreload.py\", line 397, in update_generic\n",
      "    update(a, b)\n",
      "  File \"/home/pita/Projects/py_fatigue/.venv/lib/python3.9/site-packages/IPython/extensions/autoreload.py\", line 349, in update_class\n",
      "    if update_generic(old_obj, new_obj):\n",
      "  File \"/home/pita/Projects/py_fatigue/.venv/lib/python3.9/site-packages/IPython/extensions/autoreload.py\", line 397, in update_generic\n",
      "    update(a, b)\n",
      "  File \"/home/pita/Projects/py_fatigue/.venv/lib/python3.9/site-packages/IPython/extensions/autoreload.py\", line 349, in update_class\n",
      "    if update_generic(old_obj, new_obj):\n",
      "  File \"/home/pita/Projects/py_fatigue/.venv/lib/python3.9/site-packages/IPython/extensions/autoreload.py\", line 397, in update_generic\n",
      "    update(a, b)\n",
      "  File \"/home/pita/Projects/py_fatigue/.venv/lib/python3.9/site-packages/IPython/extensions/autoreload.py\", line 309, in update_function\n",
      "    setattr(old, name, getattr(new, name))\n",
      "ValueError: __init__() requires a code object with 1 free vars, not 0\n",
      "]\n",
      "[autoreload of pandas.core.reshape.encoding failed: Traceback (most recent call last):\n",
      "  File \"/home/pita/Projects/py_fatigue/.venv/lib/python3.9/site-packages/IPython/extensions/autoreload.py\", line 276, in check\n",
      "    superreload(m, reload, self.old_objects)\n",
      "  File \"/home/pita/Projects/py_fatigue/.venv/lib/python3.9/site-packages/IPython/extensions/autoreload.py\", line 475, in superreload\n",
      "    module = reload(module)\n",
      "  File \"/home/pita/.pyenv/versions/3.9.19/lib/python3.9/importlib/__init__.py\", line 169, in reload\n",
      "    _bootstrap._exec(spec, module)\n",
      "  File \"<frozen importlib._bootstrap>\", line 613, in _exec\n",
      "  File \"<frozen importlib._bootstrap_external>\", line 850, in exec_module\n",
      "  File \"<frozen importlib._bootstrap>\", line 228, in _call_with_frames_removed\n",
      "  File \"/home/pita/Projects/py_fatigue/.venv/lib/python3.9/site-packages/pandas/core/reshape/encoding.py\", line 24, in <module>\n",
      "    from pandas.core.dtypes.dtypes import (\n",
      "ImportError: cannot import name 'ArrowDtype' from 'pandas.core.dtypes.dtypes' (/home/pita/Projects/py_fatigue/.venv/lib/python3.9/site-packages/pandas/core/dtypes/dtypes.py)\n",
      "]\n",
      "[autoreload of pandas.core.reshape.merge failed: Traceback (most recent call last):\n",
      "  File \"/home/pita/Projects/py_fatigue/.venv/lib/python3.9/site-packages/IPython/extensions/autoreload.py\", line 276, in check\n",
      "    superreload(m, reload, self.old_objects)\n",
      "  File \"/home/pita/Projects/py_fatigue/.venv/lib/python3.9/site-packages/IPython/extensions/autoreload.py\", line 475, in superreload\n",
      "    module = reload(module)\n",
      "  File \"/home/pita/.pyenv/versions/3.9.19/lib/python3.9/importlib/__init__.py\", line 169, in reload\n",
      "    _bootstrap._exec(spec, module)\n",
      "  File \"<frozen importlib._bootstrap>\", line 613, in _exec\n",
      "  File \"<frozen importlib._bootstrap_external>\", line 850, in exec_module\n",
      "  File \"<frozen importlib._bootstrap>\", line 228, in _call_with_frames_removed\n",
      "  File \"/home/pita/Projects/py_fatigue/.venv/lib/python3.9/site-packages/pandas/core/reshape/merge.py\", line 29, in <module>\n",
      "    from pandas._libs.lib import is_range_indexer\n",
      "ImportError: cannot import name 'is_range_indexer' from 'pandas._libs.lib' (/home/pita/Projects/py_fatigue/.venv/lib/python3.9/site-packages/pandas/_libs/lib.cpython-39-x86_64-linux-gnu.so)\n",
      "]\n",
      "[autoreload of pandas.core.reshape.pivot failed: Traceback (most recent call last):\n",
      "  File \"/home/pita/Projects/py_fatigue/.venv/lib/python3.9/site-packages/IPython/extensions/autoreload.py\", line 276, in check\n",
      "    superreload(m, reload, self.old_objects)\n",
      "  File \"/home/pita/Projects/py_fatigue/.venv/lib/python3.9/site-packages/IPython/extensions/autoreload.py\", line 500, in superreload\n",
      "    update_generic(old_obj, new_obj)\n",
      "  File \"/home/pita/Projects/py_fatigue/.venv/lib/python3.9/site-packages/IPython/extensions/autoreload.py\", line 397, in update_generic\n",
      "    update(a, b)\n",
      "  File \"/home/pita/Projects/py_fatigue/.venv/lib/python3.9/site-packages/IPython/extensions/autoreload.py\", line 309, in update_function\n",
      "    setattr(old, name, getattr(new, name))\n",
      "ValueError: pivot() requires a code object with 4 free vars, not 0\n",
      "]\n",
      "[autoreload of pandas.core.dtypes.api failed: Traceback (most recent call last):\n",
      "  File \"/home/pita/Projects/py_fatigue/.venv/lib/python3.9/site-packages/IPython/extensions/autoreload.py\", line 276, in check\n",
      "    superreload(m, reload, self.old_objects)\n",
      "  File \"/home/pita/Projects/py_fatigue/.venv/lib/python3.9/site-packages/IPython/extensions/autoreload.py\", line 475, in superreload\n",
      "    module = reload(module)\n",
      "  File \"/home/pita/.pyenv/versions/3.9.19/lib/python3.9/importlib/__init__.py\", line 169, in reload\n",
      "    _bootstrap._exec(spec, module)\n",
      "  File \"<frozen importlib._bootstrap>\", line 613, in _exec\n",
      "  File \"<frozen importlib._bootstrap_external>\", line 850, in exec_module\n",
      "  File \"<frozen importlib._bootstrap>\", line 228, in _call_with_frames_removed\n",
      "  File \"/home/pita/Projects/py_fatigue/.venv/lib/python3.9/site-packages/pandas/core/dtypes/api.py\", line 1, in <module>\n",
      "    from pandas.core.dtypes.common import (\n",
      "ImportError: cannot import name 'is_any_real_numeric_dtype' from 'pandas.core.dtypes.common' (/home/pita/Projects/py_fatigue/.venv/lib/python3.9/site-packages/pandas/core/dtypes/common.py)\n",
      "]\n",
      "[autoreload of pandas.core.interchange.utils failed: Traceback (most recent call last):\n",
      "  File \"/home/pita/Projects/py_fatigue/.venv/lib/python3.9/site-packages/IPython/extensions/autoreload.py\", line 276, in check\n",
      "    superreload(m, reload, self.old_objects)\n",
      "  File \"/home/pita/Projects/py_fatigue/.venv/lib/python3.9/site-packages/IPython/extensions/autoreload.py\", line 475, in superreload\n",
      "    module = reload(module)\n",
      "  File \"/home/pita/.pyenv/versions/3.9.19/lib/python3.9/importlib/__init__.py\", line 169, in reload\n",
      "    _bootstrap._exec(spec, module)\n",
      "  File \"<frozen importlib._bootstrap>\", line 613, in _exec\n",
      "  File \"<frozen importlib._bootstrap_external>\", line 850, in exec_module\n",
      "  File \"<frozen importlib._bootstrap>\", line 228, in _call_with_frames_removed\n",
      "  File \"/home/pita/Projects/py_fatigue/.venv/lib/python3.9/site-packages/pandas/core/interchange/utils.py\", line 13, in <module>\n",
      "    from pandas.core.dtypes.dtypes import (\n",
      "ImportError: cannot import name 'ArrowDtype' from 'pandas.core.dtypes.dtypes' (/home/pita/Projects/py_fatigue/.venv/lib/python3.9/site-packages/pandas/core/dtypes/dtypes.py)\n",
      "]\n",
      "[autoreload of pandas.api failed: Traceback (most recent call last):\n",
      "  File \"/home/pita/Projects/py_fatigue/.venv/lib/python3.9/site-packages/IPython/extensions/autoreload.py\", line 276, in check\n",
      "    superreload(m, reload, self.old_objects)\n",
      "  File \"/home/pita/Projects/py_fatigue/.venv/lib/python3.9/site-packages/IPython/extensions/autoreload.py\", line 475, in superreload\n",
      "    module = reload(module)\n",
      "  File \"/home/pita/.pyenv/versions/3.9.19/lib/python3.9/importlib/__init__.py\", line 169, in reload\n",
      "    _bootstrap._exec(spec, module)\n",
      "  File \"<frozen importlib._bootstrap>\", line 613, in _exec\n",
      "  File \"<frozen importlib._bootstrap_external>\", line 850, in exec_module\n",
      "  File \"<frozen importlib._bootstrap>\", line 228, in _call_with_frames_removed\n",
      "  File \"/home/pita/Projects/py_fatigue/.venv/lib/python3.9/site-packages/pandas/api/__init__.py\", line 2, in <module>\n",
      "    from pandas.api import (\n",
      "  File \"/home/pita/Projects/py_fatigue/.venv/lib/python3.9/site-packages/pandas/api/typing/__init__.py\", line 12, in <module>\n",
      "    from pandas.core.resample import (\n",
      "  File \"/home/pita/Projects/py_fatigue/.venv/lib/python3.9/site-packages/pandas/core/resample.py\", line 27, in <module>\n",
      "    from pandas._libs.tslibs.dtypes import freq_to_period_freqstr\n",
      "ImportError: cannot import name 'freq_to_period_freqstr' from 'pandas._libs.tslibs.dtypes' (/home/pita/Projects/py_fatigue/.venv/lib/python3.9/site-packages/pandas/_libs/tslibs/dtypes.cpython-39-x86_64-linux-gnu.so)\n",
      "]\n",
      "[autoreload of pandas._testing.asserters failed: Traceback (most recent call last):\n",
      "  File \"/home/pita/Projects/py_fatigue/.venv/lib/python3.9/site-packages/IPython/extensions/autoreload.py\", line 276, in check\n",
      "    superreload(m, reload, self.old_objects)\n",
      "  File \"/home/pita/Projects/py_fatigue/.venv/lib/python3.9/site-packages/IPython/extensions/autoreload.py\", line 475, in superreload\n",
      "    module = reload(module)\n",
      "  File \"/home/pita/.pyenv/versions/3.9.19/lib/python3.9/importlib/__init__.py\", line 169, in reload\n",
      "    _bootstrap._exec(spec, module)\n",
      "  File \"<frozen importlib._bootstrap>\", line 613, in _exec\n",
      "  File \"<frozen importlib._bootstrap_external>\", line 850, in exec_module\n",
      "  File \"<frozen importlib._bootstrap>\", line 228, in _call_with_frames_removed\n",
      "  File \"/home/pita/Projects/py_fatigue/.venv/lib/python3.9/site-packages/pandas/_testing/asserters.py\", line 27, in <module>\n",
      "    from pandas.core.dtypes.dtypes import (\n",
      "ImportError: cannot import name 'NumpyEADtype' from 'pandas.core.dtypes.dtypes' (/home/pita/Projects/py_fatigue/.venv/lib/python3.9/site-packages/pandas/core/dtypes/dtypes.py)\n",
      "]\n",
      "[autoreload of pandas._testing failed: Traceback (most recent call last):\n",
      "  File \"/home/pita/Projects/py_fatigue/.venv/lib/python3.9/site-packages/IPython/extensions/autoreload.py\", line 276, in check\n",
      "    superreload(m, reload, self.old_objects)\n",
      "  File \"/home/pita/Projects/py_fatigue/.venv/lib/python3.9/site-packages/IPython/extensions/autoreload.py\", line 475, in superreload\n",
      "    module = reload(module)\n",
      "  File \"/home/pita/.pyenv/versions/3.9.19/lib/python3.9/importlib/__init__.py\", line 169, in reload\n",
      "    _bootstrap._exec(spec, module)\n",
      "  File \"<frozen importlib._bootstrap>\", line 613, in _exec\n",
      "  File \"<frozen importlib._bootstrap_external>\", line 850, in exec_module\n",
      "  File \"<frozen importlib._bootstrap>\", line 228, in _call_with_frames_removed\n",
      "  File \"/home/pita/Projects/py_fatigue/.venv/lib/python3.9/site-packages/pandas/_testing/__init__.py\", line 84, in <module>\n",
      "    from pandas.core.arrays import (\n",
      "ImportError: cannot import name 'NumpyExtensionArray' from 'pandas.core.arrays' (/home/pita/Projects/py_fatigue/.venv/lib/python3.9/site-packages/pandas/core/arrays/__init__.py)\n",
      "]\n",
      "[autoreload of pandas.io.parsers.readers failed: Traceback (most recent call last):\n",
      "  File \"/home/pita/Projects/py_fatigue/.venv/lib/python3.9/site-packages/IPython/extensions/autoreload.py\", line 276, in check\n",
      "    superreload(m, reload, self.old_objects)\n",
      "  File \"/home/pita/Projects/py_fatigue/.venv/lib/python3.9/site-packages/IPython/extensions/autoreload.py\", line 500, in superreload\n",
      "    update_generic(old_obj, new_obj)\n",
      "  File \"/home/pita/Projects/py_fatigue/.venv/lib/python3.9/site-packages/IPython/extensions/autoreload.py\", line 397, in update_generic\n",
      "    update(a, b)\n",
      "  File \"/home/pita/Projects/py_fatigue/.venv/lib/python3.9/site-packages/IPython/extensions/autoreload.py\", line 309, in update_function\n",
      "    setattr(old, name, getattr(new, name))\n",
      "ValueError: read_csv() requires a code object with 5 free vars, not 0\n",
      "]\n",
      "[autoreload of pandas.io.excel._odfreader failed: Traceback (most recent call last):\n",
      "  File \"/home/pita/Projects/py_fatigue/.venv/lib/python3.9/site-packages/IPython/extensions/autoreload.py\", line 276, in check\n",
      "    superreload(m, reload, self.old_objects)\n",
      "  File \"/home/pita/Projects/py_fatigue/.venv/lib/python3.9/site-packages/IPython/extensions/autoreload.py\", line 475, in superreload\n",
      "    module = reload(module)\n",
      "  File \"/home/pita/.pyenv/versions/3.9.19/lib/python3.9/importlib/__init__.py\", line 169, in reload\n",
      "    _bootstrap._exec(spec, module)\n",
      "  File \"<frozen importlib._bootstrap>\", line 613, in _exec\n",
      "  File \"<frozen importlib._bootstrap_external>\", line 850, in exec_module\n",
      "  File \"<frozen importlib._bootstrap>\", line 228, in _call_with_frames_removed\n",
      "  File \"/home/pita/Projects/py_fatigue/.venv/lib/python3.9/site-packages/pandas/io/excel/_odfreader.py\", line 31, in <module>\n",
      "    class ODFReader(BaseExcelReader[\"OpenDocument\"]):\n",
      "TypeError: 'ABCMeta' object is not subscriptable\n",
      "]\n",
      "[autoreload of pandas.io.excel._openpyxl failed: Traceback (most recent call last):\n",
      "  File \"/home/pita/Projects/py_fatigue/.venv/lib/python3.9/site-packages/IPython/extensions/autoreload.py\", line 276, in check\n",
      "    superreload(m, reload, self.old_objects)\n",
      "  File \"/home/pita/Projects/py_fatigue/.venv/lib/python3.9/site-packages/IPython/extensions/autoreload.py\", line 475, in superreload\n",
      "    module = reload(module)\n",
      "  File \"/home/pita/.pyenv/versions/3.9.19/lib/python3.9/importlib/__init__.py\", line 169, in reload\n",
      "    _bootstrap._exec(spec, module)\n",
      "  File \"<frozen importlib._bootstrap>\", line 613, in _exec\n",
      "  File \"<frozen importlib._bootstrap_external>\", line 850, in exec_module\n",
      "  File \"<frozen importlib._bootstrap>\", line 228, in _call_with_frames_removed\n",
      "  File \"/home/pita/Projects/py_fatigue/.venv/lib/python3.9/site-packages/pandas/io/excel/_openpyxl.py\", line 533, in <module>\n",
      "    class OpenpyxlReader(BaseExcelReader[\"Workbook\"]):\n",
      "TypeError: 'ABCMeta' object is not subscriptable\n",
      "]\n",
      "[autoreload of pandas.io.excel._pyxlsb failed: Traceback (most recent call last):\n",
      "  File \"/home/pita/Projects/py_fatigue/.venv/lib/python3.9/site-packages/IPython/extensions/autoreload.py\", line 276, in check\n",
      "    superreload(m, reload, self.old_objects)\n",
      "  File \"/home/pita/Projects/py_fatigue/.venv/lib/python3.9/site-packages/IPython/extensions/autoreload.py\", line 475, in superreload\n",
      "    module = reload(module)\n",
      "  File \"/home/pita/.pyenv/versions/3.9.19/lib/python3.9/importlib/__init__.py\", line 169, in reload\n",
      "    _bootstrap._exec(spec, module)\n",
      "  File \"<frozen importlib._bootstrap>\", line 613, in _exec\n",
      "  File \"<frozen importlib._bootstrap_external>\", line 850, in exec_module\n",
      "  File \"<frozen importlib._bootstrap>\", line 228, in _call_with_frames_removed\n",
      "  File \"/home/pita/Projects/py_fatigue/.venv/lib/python3.9/site-packages/pandas/io/excel/_pyxlsb.py\", line 24, in <module>\n",
      "    class PyxlsbReader(BaseExcelReader[\"Workbook\"]):\n",
      "TypeError: 'ABCMeta' object is not subscriptable\n",
      "]\n",
      "[autoreload of pandas.io.excel._xlrd failed: Traceback (most recent call last):\n",
      "  File \"/home/pita/Projects/py_fatigue/.venv/lib/python3.9/site-packages/IPython/extensions/autoreload.py\", line 276, in check\n",
      "    superreload(m, reload, self.old_objects)\n",
      "  File \"/home/pita/Projects/py_fatigue/.venv/lib/python3.9/site-packages/IPython/extensions/autoreload.py\", line 475, in superreload\n",
      "    module = reload(module)\n",
      "  File \"/home/pita/.pyenv/versions/3.9.19/lib/python3.9/importlib/__init__.py\", line 169, in reload\n",
      "    _bootstrap._exec(spec, module)\n",
      "  File \"<frozen importlib._bootstrap>\", line 613, in _exec\n",
      "  File \"<frozen importlib._bootstrap_external>\", line 850, in exec_module\n",
      "  File \"<frozen importlib._bootstrap>\", line 228, in _call_with_frames_removed\n",
      "  File \"/home/pita/Projects/py_fatigue/.venv/lib/python3.9/site-packages/pandas/io/excel/_xlrd.py\", line 25, in <module>\n",
      "    class XlrdReader(BaseExcelReader[\"Book\"]):\n",
      "TypeError: 'ABCMeta' object is not subscriptable\n",
      "]\n",
      "[autoreload of pandas.io.excel._base failed: Traceback (most recent call last):\n",
      "  File \"/home/pita/Projects/py_fatigue/.venv/lib/python3.9/site-packages/IPython/extensions/autoreload.py\", line 276, in check\n",
      "    superreload(m, reload, self.old_objects)\n",
      "  File \"/home/pita/Projects/py_fatigue/.venv/lib/python3.9/site-packages/IPython/extensions/autoreload.py\", line 500, in superreload\n",
      "    update_generic(old_obj, new_obj)\n",
      "  File \"/home/pita/Projects/py_fatigue/.venv/lib/python3.9/site-packages/IPython/extensions/autoreload.py\", line 397, in update_generic\n",
      "    update(a, b)\n",
      "  File \"/home/pita/Projects/py_fatigue/.venv/lib/python3.9/site-packages/IPython/extensions/autoreload.py\", line 309, in update_function\n",
      "    setattr(old, name, getattr(new, name))\n",
      "ValueError: read_excel() requires a code object with 5 free vars, not 0\n",
      "]\n",
      "[autoreload of pandas.io.html failed: Traceback (most recent call last):\n",
      "  File \"/home/pita/Projects/py_fatigue/.venv/lib/python3.9/site-packages/IPython/extensions/autoreload.py\", line 276, in check\n",
      "    superreload(m, reload, self.old_objects)\n",
      "  File \"/home/pita/Projects/py_fatigue/.venv/lib/python3.9/site-packages/IPython/extensions/autoreload.py\", line 500, in superreload\n",
      "    update_generic(old_obj, new_obj)\n",
      "  File \"/home/pita/Projects/py_fatigue/.venv/lib/python3.9/site-packages/IPython/extensions/autoreload.py\", line 397, in update_generic\n",
      "    update(a, b)\n",
      "  File \"/home/pita/Projects/py_fatigue/.venv/lib/python3.9/site-packages/IPython/extensions/autoreload.py\", line 349, in update_class\n",
      "    if update_generic(old_obj, new_obj):\n",
      "  File \"/home/pita/Projects/py_fatigue/.venv/lib/python3.9/site-packages/IPython/extensions/autoreload.py\", line 397, in update_generic\n",
      "    update(a, b)\n",
      "  File \"/home/pita/Projects/py_fatigue/.venv/lib/python3.9/site-packages/IPython/extensions/autoreload.py\", line 309, in update_function\n",
      "    setattr(old, name, getattr(new, name))\n",
      "ValueError: __init__() requires a code object with 1 free vars, not 0\n",
      "]\n",
      "[autoreload of pandas.io.json._normalize failed: Traceback (most recent call last):\n",
      "  File \"/home/pita/Projects/py_fatigue/.venv/lib/python3.9/site-packages/IPython/extensions/autoreload.py\", line 276, in check\n",
      "    superreload(m, reload, self.old_objects)\n",
      "  File \"/home/pita/Projects/py_fatigue/.venv/lib/python3.9/site-packages/IPython/extensions/autoreload.py\", line 500, in superreload\n",
      "    update_generic(old_obj, new_obj)\n",
      "  File \"/home/pita/Projects/py_fatigue/.venv/lib/python3.9/site-packages/IPython/extensions/autoreload.py\", line 397, in update_generic\n",
      "    update(a, b)\n",
      "  File \"/home/pita/Projects/py_fatigue/.venv/lib/python3.9/site-packages/IPython/extensions/autoreload.py\", line 309, in update_function\n",
      "    setattr(old, name, getattr(new, name))\n",
      "ValueError: _json_normalize() requires a code object with 4 free vars, not 0\n",
      "]\n",
      "[autoreload of pandas.io.json._table_schema failed: Traceback (most recent call last):\n",
      "  File \"/home/pita/Projects/py_fatigue/.venv/lib/python3.9/site-packages/IPython/extensions/autoreload.py\", line 276, in check\n",
      "    superreload(m, reload, self.old_objects)\n",
      "  File \"/home/pita/Projects/py_fatigue/.venv/lib/python3.9/site-packages/IPython/extensions/autoreload.py\", line 475, in superreload\n",
      "    module = reload(module)\n",
      "  File \"/home/pita/.pyenv/versions/3.9.19/lib/python3.9/importlib/__init__.py\", line 169, in reload\n",
      "    _bootstrap._exec(spec, module)\n",
      "  File \"<frozen importlib._bootstrap>\", line 613, in _exec\n",
      "  File \"<frozen importlib._bootstrap_external>\", line 850, in exec_module\n",
      "  File \"<frozen importlib._bootstrap>\", line 228, in _call_with_frames_removed\n",
      "  File \"/home/pita/Projects/py_fatigue/.venv/lib/python3.9/site-packages/pandas/io/json/_table_schema.py\", line 16, in <module>\n",
      "    from pandas._libs.json import ujson_loads\n",
      "ImportError: cannot import name 'ujson_loads' from 'pandas._libs.json' (/home/pita/Projects/py_fatigue/.venv/lib/python3.9/site-packages/pandas/_libs/json.cpython-39-x86_64-linux-gnu.so)\n",
      "]\n",
      "[autoreload of pandas.io.json._json failed: Traceback (most recent call last):\n",
      "  File \"/home/pita/Projects/py_fatigue/.venv/lib/python3.9/site-packages/IPython/extensions/autoreload.py\", line 276, in check\n",
      "    superreload(m, reload, self.old_objects)\n",
      "  File \"/home/pita/Projects/py_fatigue/.venv/lib/python3.9/site-packages/IPython/extensions/autoreload.py\", line 475, in superreload\n",
      "    module = reload(module)\n",
      "  File \"/home/pita/.pyenv/versions/3.9.19/lib/python3.9/importlib/__init__.py\", line 169, in reload\n",
      "    _bootstrap._exec(spec, module)\n",
      "  File \"<frozen importlib._bootstrap>\", line 613, in _exec\n",
      "  File \"<frozen importlib._bootstrap_external>\", line 850, in exec_module\n",
      "  File \"<frozen importlib._bootstrap>\", line 228, in _call_with_frames_removed\n",
      "  File \"/home/pita/Projects/py_fatigue/.venv/lib/python3.9/site-packages/pandas/io/json/_json.py\", line 25, in <module>\n",
      "    from pandas._libs.json import (\n",
      "ImportError: cannot import name 'ujson_dumps' from 'pandas._libs.json' (/home/pita/Projects/py_fatigue/.venv/lib/python3.9/site-packages/pandas/_libs/json.cpython-39-x86_64-linux-gnu.so)\n",
      "]\n",
      "[autoreload of pandas.io.json failed: Traceback (most recent call last):\n",
      "  File \"/home/pita/Projects/py_fatigue/.venv/lib/python3.9/site-packages/IPython/extensions/autoreload.py\", line 276, in check\n",
      "    superreload(m, reload, self.old_objects)\n",
      "  File \"/home/pita/Projects/py_fatigue/.venv/lib/python3.9/site-packages/IPython/extensions/autoreload.py\", line 475, in superreload\n",
      "    module = reload(module)\n",
      "  File \"/home/pita/.pyenv/versions/3.9.19/lib/python3.9/importlib/__init__.py\", line 169, in reload\n",
      "    _bootstrap._exec(spec, module)\n",
      "  File \"<frozen importlib._bootstrap>\", line 613, in _exec\n",
      "  File \"<frozen importlib._bootstrap_external>\", line 850, in exec_module\n",
      "  File \"<frozen importlib._bootstrap>\", line 228, in _call_with_frames_removed\n",
      "  File \"/home/pita/Projects/py_fatigue/.venv/lib/python3.9/site-packages/pandas/io/json/__init__.py\", line 1, in <module>\n",
      "    from pandas.io.json._json import (\n",
      "ImportError: cannot import name 'ujson_dumps' from 'pandas.io.json._json' (/home/pita/Projects/py_fatigue/.venv/lib/python3.9/site-packages/pandas/io/json/_json.py)\n",
      "]\n",
      "[autoreload of pandas.io.sas.sasreader failed: Traceback (most recent call last):\n",
      "  File \"/home/pita/Projects/py_fatigue/.venv/lib/python3.9/site-packages/IPython/extensions/autoreload.py\", line 276, in check\n",
      "    superreload(m, reload, self.old_objects)\n",
      "  File \"/home/pita/Projects/py_fatigue/.venv/lib/python3.9/site-packages/IPython/extensions/autoreload.py\", line 500, in superreload\n",
      "    update_generic(old_obj, new_obj)\n",
      "  File \"/home/pita/Projects/py_fatigue/.venv/lib/python3.9/site-packages/IPython/extensions/autoreload.py\", line 397, in update_generic\n",
      "    update(a, b)\n",
      "  File \"/home/pita/Projects/py_fatigue/.venv/lib/python3.9/site-packages/IPython/extensions/autoreload.py\", line 309, in update_function\n",
      "    setattr(old, name, getattr(new, name))\n",
      "ValueError: read_sas() requires a code object with 4 free vars, not 0\n",
      "]\n",
      "[autoreload of pandas.io.sql failed: Traceback (most recent call last):\n",
      "  File \"/home/pita/Projects/py_fatigue/.venv/lib/python3.9/site-packages/IPython/extensions/autoreload.py\", line 276, in check\n",
      "    superreload(m, reload, self.old_objects)\n",
      "  File \"/home/pita/Projects/py_fatigue/.venv/lib/python3.9/site-packages/IPython/extensions/autoreload.py\", line 475, in superreload\n",
      "    module = reload(module)\n",
      "  File \"/home/pita/.pyenv/versions/3.9.19/lib/python3.9/importlib/__init__.py\", line 169, in reload\n",
      "    _bootstrap._exec(spec, module)\n",
      "  File \"<frozen importlib._bootstrap>\", line 613, in _exec\n",
      "  File \"<frozen importlib._bootstrap_external>\", line 850, in exec_module\n",
      "  File \"<frozen importlib._bootstrap>\", line 228, in _call_with_frames_removed\n",
      "  File \"/home/pita/Projects/py_fatigue/.venv/lib/python3.9/site-packages/pandas/io/sql.py\", line 50, in <module>\n",
      "    from pandas.core.dtypes.dtypes import (\n",
      "ImportError: cannot import name 'ArrowDtype' from 'pandas.core.dtypes.dtypes' (/home/pita/Projects/py_fatigue/.venv/lib/python3.9/site-packages/pandas/core/dtypes/dtypes.py)\n",
      "]\n",
      "[autoreload of pandas.io.stata failed: Traceback (most recent call last):\n",
      "  File \"/home/pita/Projects/py_fatigue/.venv/lib/python3.9/site-packages/IPython/extensions/autoreload.py\", line 276, in check\n",
      "    superreload(m, reload, self.old_objects)\n",
      "  File \"/home/pita/Projects/py_fatigue/.venv/lib/python3.9/site-packages/IPython/extensions/autoreload.py\", line 500, in superreload\n",
      "    update_generic(old_obj, new_obj)\n",
      "  File \"/home/pita/Projects/py_fatigue/.venv/lib/python3.9/site-packages/IPython/extensions/autoreload.py\", line 397, in update_generic\n",
      "    update(a, b)\n",
      "  File \"/home/pita/Projects/py_fatigue/.venv/lib/python3.9/site-packages/IPython/extensions/autoreload.py\", line 309, in update_function\n",
      "    setattr(old, name, getattr(new, name))\n",
      "ValueError: read_stata() requires a code object with 4 free vars, not 0\n",
      "]\n",
      "[autoreload of pandas.io.xml failed: Traceback (most recent call last):\n",
      "  File \"/home/pita/Projects/py_fatigue/.venv/lib/python3.9/site-packages/IPython/extensions/autoreload.py\", line 276, in check\n",
      "    superreload(m, reload, self.old_objects)\n",
      "  File \"/home/pita/Projects/py_fatigue/.venv/lib/python3.9/site-packages/IPython/extensions/autoreload.py\", line 500, in superreload\n",
      "    update_generic(old_obj, new_obj)\n",
      "  File \"/home/pita/Projects/py_fatigue/.venv/lib/python3.9/site-packages/IPython/extensions/autoreload.py\", line 397, in update_generic\n",
      "    update(a, b)\n",
      "  File \"/home/pita/Projects/py_fatigue/.venv/lib/python3.9/site-packages/IPython/extensions/autoreload.py\", line 309, in update_function\n",
      "    setattr(old, name, getattr(new, name))\n",
      "ValueError: read_xml() requires a code object with 4 free vars, not 0\n",
      "]\n",
      "[autoreload of pandas failed: Traceback (most recent call last):\n",
      "  File \"/home/pita/Projects/py_fatigue/.venv/lib/python3.9/site-packages/IPython/extensions/autoreload.py\", line 276, in check\n",
      "    superreload(m, reload, self.old_objects)\n",
      "  File \"/home/pita/Projects/py_fatigue/.venv/lib/python3.9/site-packages/IPython/extensions/autoreload.py\", line 475, in superreload\n",
      "    module = reload(module)\n",
      "  File \"/home/pita/.pyenv/versions/3.9.19/lib/python3.9/importlib/__init__.py\", line 169, in reload\n",
      "    _bootstrap._exec(spec, module)\n",
      "  File \"<frozen importlib._bootstrap>\", line 613, in _exec\n",
      "  File \"<frozen importlib._bootstrap_external>\", line 850, in exec_module\n",
      "  File \"<frozen importlib._bootstrap>\", line 228, in _call_with_frames_removed\n",
      "  File \"/home/pita/Projects/py_fatigue/.venv/lib/python3.9/site-packages/pandas/__init__.py\", line 114, in <module>\n",
      "    from pandas.core.dtypes.dtypes import SparseDtype\n",
      "ImportError: cannot import name 'SparseDtype' from 'pandas.core.dtypes.dtypes' (/home/pita/Projects/py_fatigue/.venv/lib/python3.9/site-packages/pandas/core/dtypes/dtypes.py)\n",
      "]\n",
      "[autoreload of llvmlite.binding.ffi failed: Traceback (most recent call last):\n",
      "  File \"/home/pita/Projects/py_fatigue/.venv/lib/python3.9/site-packages/IPython/extensions/autoreload.py\", line 276, in check\n",
      "    superreload(m, reload, self.old_objects)\n",
      "  File \"/home/pita/Projects/py_fatigue/.venv/lib/python3.9/site-packages/IPython/extensions/autoreload.py\", line 500, in superreload\n",
      "    update_generic(old_obj, new_obj)\n",
      "  File \"/home/pita/Projects/py_fatigue/.venv/lib/python3.9/site-packages/IPython/extensions/autoreload.py\", line 397, in update_generic\n",
      "    update(a, b)\n",
      "  File \"/home/pita/Projects/py_fatigue/.venv/lib/python3.9/site-packages/IPython/extensions/autoreload.py\", line 365, in update_class\n",
      "    update_instances(old, new)\n",
      "  File \"/home/pita/Projects/py_fatigue/.venv/lib/python3.9/site-packages/IPython/extensions/autoreload.py\", line 323, in update_instances\n",
      "    object.__setattr__(ref, \"__class__\", new)\n",
      "TypeError: __class__ assignment: '_lib_wrapper' object layout differs from '_lib_wrapper'\n",
      "]\n",
      "[autoreload of llvmlite.binding.value failed: Traceback (most recent call last):\n",
      "  File \"/home/pita/Projects/py_fatigue/.venv/lib/python3.9/site-packages/llvmlite/binding/ffi.py\", line 136, in __getattr__\n",
      "    return self._fntab[name]\n",
      "KeyError: 'LLVMPY_TypeIsArray'\n",
      "\n",
      "During handling of the above exception, another exception occurred:\n",
      "\n",
      "Traceback (most recent call last):\n",
      "  File \"/home/pita/Projects/py_fatigue/.venv/lib/python3.9/site-packages/IPython/extensions/autoreload.py\", line 276, in check\n",
      "    superreload(m, reload, self.old_objects)\n",
      "  File \"/home/pita/Projects/py_fatigue/.venv/lib/python3.9/site-packages/IPython/extensions/autoreload.py\", line 475, in superreload\n",
      "    module = reload(module)\n",
      "  File \"/home/pita/.pyenv/versions/3.9.19/lib/python3.9/importlib/__init__.py\", line 169, in reload\n",
      "    _bootstrap._exec(spec, module)\n",
      "  File \"<frozen importlib._bootstrap>\", line 613, in _exec\n",
      "  File \"<frozen importlib._bootstrap_external>\", line 850, in exec_module\n",
      "  File \"<frozen importlib._bootstrap>\", line 228, in _call_with_frames_removed\n",
      "  File \"/home/pita/Projects/py_fatigue/.venv/lib/python3.9/site-packages/llvmlite/binding/value.py\", line 7, in <module>\n",
      "    from llvmlite.binding.typeref import TypeRef\n",
      "  File \"/home/pita/Projects/py_fatigue/.venv/lib/python3.9/site-packages/llvmlite/binding/typeref.py\", line 171, in <module>\n",
      "    ffi.lib.LLVMPY_TypeIsArray.argtypes = [ffi.LLVMTypeRef]\n",
      "  File \"/home/pita/Projects/py_fatigue/.venv/lib/python3.9/site-packages/llvmlite/binding/ffi.py\", line 139, in __getattr__\n",
      "    cfn = getattr(self._lib, name)\n",
      "  File \"/home/pita/.pyenv/versions/3.9.19/lib/python3.9/ctypes/__init__.py\", line 387, in __getattr__\n",
      "    func = self.__getitem__(name)\n",
      "AttributeError: /home/pita/Projects/py_fatigue/.venv/lib/python3.9/site-packages/llvmlite/binding/libllvmlite.so: undefined symbol: LLVMPY_TypeIsArray\n",
      "]\n",
      "[autoreload of llvmlite.binding.passmanagers failed: Traceback (most recent call last):\n",
      "  File \"/home/pita/Projects/py_fatigue/.venv/lib/python3.9/site-packages/llvmlite/binding/ffi.py\", line 136, in __getattr__\n",
      "    return self._fntab[name]\n",
      "KeyError: 'LLVMPY_AddAAEvalPass'\n",
      "\n",
      "During handling of the above exception, another exception occurred:\n",
      "\n",
      "Traceback (most recent call last):\n",
      "  File \"/home/pita/Projects/py_fatigue/.venv/lib/python3.9/site-packages/IPython/extensions/autoreload.py\", line 276, in check\n",
      "    superreload(m, reload, self.old_objects)\n",
      "  File \"/home/pita/Projects/py_fatigue/.venv/lib/python3.9/site-packages/IPython/extensions/autoreload.py\", line 475, in superreload\n",
      "    module = reload(module)\n",
      "  File \"/home/pita/.pyenv/versions/3.9.19/lib/python3.9/importlib/__init__.py\", line 169, in reload\n",
      "    _bootstrap._exec(spec, module)\n",
      "  File \"<frozen importlib._bootstrap>\", line 613, in _exec\n",
      "  File \"<frozen importlib._bootstrap_external>\", line 850, in exec_module\n",
      "  File \"<frozen importlib._bootstrap>\", line 228, in _call_with_frames_removed\n",
      "  File \"/home/pita/Projects/py_fatigue/.venv/lib/python3.9/site-packages/llvmlite/binding/passmanagers.py\", line 853, in <module>\n",
      "    ffi.lib.LLVMPY_AddAAEvalPass.argtypes = [ffi.LLVMPassManagerRef]\n",
      "  File \"/home/pita/Projects/py_fatigue/.venv/lib/python3.9/site-packages/llvmlite/binding/ffi.py\", line 139, in __getattr__\n",
      "    cfn = getattr(self._lib, name)\n",
      "  File \"/home/pita/.pyenv/versions/3.9.19/lib/python3.9/ctypes/__init__.py\", line 387, in __getattr__\n",
      "    func = self.__getitem__(name)\n",
      "  File \"/home/pita/.pyenv/versions/3.9.19/lib/python3.9/ctypes/__init__.py\", line 392, in __getitem__\n",
      "    func = self._FuncPtr((name_or_ordinal, self))\n",
      "AttributeError: /home/pita/Projects/py_fatigue/.venv/lib/python3.9/site-packages/llvmlite/binding/libllvmlite.so: undefined symbol: LLVMPY_AddAAEvalPass\n",
      "]\n",
      "[autoreload of llvmlite.ir.values failed: Traceback (most recent call last):\n",
      "  File \"/home/pita/Projects/py_fatigue/.venv/lib/python3.9/site-packages/IPython/extensions/autoreload.py\", line 276, in check\n",
      "    superreload(m, reload, self.old_objects)\n",
      "  File \"/home/pita/Projects/py_fatigue/.venv/lib/python3.9/site-packages/IPython/extensions/autoreload.py\", line 500, in superreload\n",
      "    update_generic(old_obj, new_obj)\n",
      "  File \"/home/pita/Projects/py_fatigue/.venv/lib/python3.9/site-packages/IPython/extensions/autoreload.py\", line 397, in update_generic\n",
      "    update(a, b)\n",
      "  File \"/home/pita/Projects/py_fatigue/.venv/lib/python3.9/site-packages/IPython/extensions/autoreload.py\", line 349, in update_class\n",
      "    if update_generic(old_obj, new_obj):\n",
      "  File \"/home/pita/Projects/py_fatigue/.venv/lib/python3.9/site-packages/IPython/extensions/autoreload.py\", line 397, in update_generic\n",
      "    update(a, b)\n",
      "  File \"/home/pita/Projects/py_fatigue/.venv/lib/python3.9/site-packages/IPython/extensions/autoreload.py\", line 309, in update_function\n",
      "    setattr(old, name, getattr(new, name))\n",
      "ValueError: __init__() requires a code object with 0 free vars, not 1\n",
      "]\n",
      "[autoreload of llvmlite.binding failed: Traceback (most recent call last):\n",
      "  File \"/home/pita/Projects/py_fatigue/.venv/lib/python3.9/site-packages/llvmlite/binding/ffi.py\", line 136, in __getattr__\n",
      "    return self._fntab[name]\n",
      "KeyError: 'LLVMPY_TypeIsArray'\n",
      "\n",
      "During handling of the above exception, another exception occurred:\n",
      "\n",
      "Traceback (most recent call last):\n",
      "  File \"/home/pita/Projects/py_fatigue/.venv/lib/python3.9/site-packages/IPython/extensions/autoreload.py\", line 276, in check\n",
      "    superreload(m, reload, self.old_objects)\n",
      "  File \"/home/pita/Projects/py_fatigue/.venv/lib/python3.9/site-packages/IPython/extensions/autoreload.py\", line 475, in superreload\n",
      "    module = reload(module)\n",
      "  File \"/home/pita/.pyenv/versions/3.9.19/lib/python3.9/importlib/__init__.py\", line 169, in reload\n",
      "    _bootstrap._exec(spec, module)\n",
      "  File \"<frozen importlib._bootstrap>\", line 613, in _exec\n",
      "  File \"<frozen importlib._bootstrap_external>\", line 850, in exec_module\n",
      "  File \"<frozen importlib._bootstrap>\", line 228, in _call_with_frames_removed\n",
      "  File \"/home/pita/Projects/py_fatigue/.venv/lib/python3.9/site-packages/llvmlite/binding/__init__.py\", line 14, in <module>\n",
      "    from .typeref import *\n",
      "  File \"/home/pita/Projects/py_fatigue/.venv/lib/python3.9/site-packages/llvmlite/binding/typeref.py\", line 171, in <module>\n",
      "    ffi.lib.LLVMPY_TypeIsArray.argtypes = [ffi.LLVMTypeRef]\n",
      "  File \"/home/pita/Projects/py_fatigue/.venv/lib/python3.9/site-packages/llvmlite/binding/ffi.py\", line 139, in __getattr__\n",
      "    cfn = getattr(self._lib, name)\n",
      "  File \"/home/pita/.pyenv/versions/3.9.19/lib/python3.9/ctypes/__init__.py\", line 387, in __getattr__\n",
      "    func = self.__getitem__(name)\n",
      "AttributeError: /home/pita/Projects/py_fatigue/.venv/lib/python3.9/site-packages/llvmlite/binding/libllvmlite.so: undefined symbol: LLVMPY_TypeIsArray\n",
      "]\n",
      "[autoreload of numba.core.types.abstract failed: Traceback (most recent call last):\n",
      "  File \"/home/pita/Projects/py_fatigue/.venv/lib/python3.9/site-packages/IPython/extensions/autoreload.py\", line 276, in check\n",
      "    superreload(m, reload, self.old_objects)\n",
      "  File \"/home/pita/Projects/py_fatigue/.venv/lib/python3.9/site-packages/IPython/extensions/autoreload.py\", line 500, in superreload\n",
      "    update_generic(old_obj, new_obj)\n",
      "  File \"/home/pita/Projects/py_fatigue/.venv/lib/python3.9/site-packages/IPython/extensions/autoreload.py\", line 397, in update_generic\n",
      "    update(a, b)\n",
      "  File \"/home/pita/Projects/py_fatigue/.venv/lib/python3.9/site-packages/IPython/extensions/autoreload.py\", line 365, in update_class\n",
      "    update_instances(old, new)\n",
      "  File \"/home/pita/Projects/py_fatigue/.venv/lib/python3.9/site-packages/IPython/extensions/autoreload.py\", line 323, in update_instances\n",
      "    object.__setattr__(ref, \"__class__\", new)\n",
      "TypeError: can't apply this __setattr__ to _TypeMetaclass object\n",
      "]\n",
      "[autoreload of numba.core.targetconfig failed: Traceback (most recent call last):\n",
      "  File \"/home/pita/Projects/py_fatigue/.venv/lib/python3.9/site-packages/IPython/extensions/autoreload.py\", line 276, in check\n",
      "    superreload(m, reload, self.old_objects)\n",
      "  File \"/home/pita/Projects/py_fatigue/.venv/lib/python3.9/site-packages/IPython/extensions/autoreload.py\", line 500, in superreload\n",
      "    update_generic(old_obj, new_obj)\n",
      "  File \"/home/pita/Projects/py_fatigue/.venv/lib/python3.9/site-packages/IPython/extensions/autoreload.py\", line 397, in update_generic\n",
      "    update(a, b)\n",
      "  File \"/home/pita/Projects/py_fatigue/.venv/lib/python3.9/site-packages/IPython/extensions/autoreload.py\", line 365, in update_class\n",
      "    update_instances(old, new)\n",
      "  File \"/home/pita/Projects/py_fatigue/.venv/lib/python3.9/site-packages/IPython/extensions/autoreload.py\", line 323, in update_instances\n",
      "    object.__setattr__(ref, \"__class__\", new)\n",
      "TypeError: can't apply this __setattr__ to _MetaTargetConfig object\n",
      "]\n",
      "[autoreload of numba.core.cpu_options failed: Traceback (most recent call last):\n",
      "  File \"/home/pita/Projects/py_fatigue/.venv/lib/python3.9/site-packages/IPython/extensions/autoreload.py\", line 276, in check\n",
      "    superreload(m, reload, self.old_objects)\n",
      "  File \"/home/pita/Projects/py_fatigue/.venv/lib/python3.9/site-packages/IPython/extensions/autoreload.py\", line 500, in superreload\n",
      "    update_generic(old_obj, new_obj)\n",
      "  File \"/home/pita/Projects/py_fatigue/.venv/lib/python3.9/site-packages/IPython/extensions/autoreload.py\", line 397, in update_generic\n",
      "    update(a, b)\n",
      "  File \"/home/pita/Projects/py_fatigue/.venv/lib/python3.9/site-packages/IPython/extensions/autoreload.py\", line 365, in update_class\n",
      "    update_instances(old, new)\n",
      "  File \"/home/pita/Projects/py_fatigue/.venv/lib/python3.9/site-packages/IPython/extensions/autoreload.py\", line 323, in update_instances\n",
      "    object.__setattr__(ref, \"__class__\", new)\n",
      "TypeError: __class__ assignment: 'ParallelOptions' object layout differs from 'ParallelOptions'\n",
      "]\n",
      "[autoreload of numba.core.datamodel.models failed: Traceback (most recent call last):\n",
      "  File \"/home/pita/Projects/py_fatigue/.venv/lib/python3.9/site-packages/IPython/extensions/autoreload.py\", line 276, in check\n",
      "    superreload(m, reload, self.old_objects)\n",
      "  File \"/home/pita/Projects/py_fatigue/.venv/lib/python3.9/site-packages/IPython/extensions/autoreload.py\", line 475, in superreload\n",
      "    module = reload(module)\n",
      "  File \"/home/pita/.pyenv/versions/3.9.19/lib/python3.9/importlib/__init__.py\", line 169, in reload\n",
      "    _bootstrap._exec(spec, module)\n",
      "  File \"<frozen importlib._bootstrap>\", line 613, in _exec\n",
      "  File \"<frozen importlib._bootstrap_external>\", line 850, in exec_module\n",
      "  File \"<frozen importlib._bootstrap>\", line 228, in _call_with_frames_removed\n",
      "  File \"/home/pita/Projects/py_fatigue/.venv/lib/python3.9/site-packages/numba/core/datamodel/models.py\", line 1087, in <module>\n",
      "    @register_default(types.misc.SliceLiteral)\n",
      "AttributeError: module 'numba.core.types' has no attribute 'misc'\n",
      "]\n",
      "[autoreload of numba.core.typing.typeof failed: Traceback (most recent call last):\n",
      "  File \"/home/pita/Projects/py_fatigue/.venv/lib/python3.9/site-packages/IPython/extensions/autoreload.py\", line 276, in check\n",
      "    superreload(m, reload, self.old_objects)\n",
      "  File \"/home/pita/Projects/py_fatigue/.venv/lib/python3.9/site-packages/IPython/extensions/autoreload.py\", line 475, in superreload\n",
      "    module = reload(module)\n",
      "  File \"/home/pita/.pyenv/versions/3.9.19/lib/python3.9/importlib/__init__.py\", line 169, in reload\n",
      "    _bootstrap._exec(spec, module)\n",
      "  File \"<frozen importlib._bootstrap>\", line 613, in _exec\n",
      "  File \"<frozen importlib._bootstrap_external>\", line 850, in exec_module\n",
      "  File \"<frozen importlib._bootstrap>\", line 228, in _call_with_frames_removed\n",
      "  File \"/home/pita/Projects/py_fatigue/.venv/lib/python3.9/site-packages/numba/core/typing/typeof.py\", line 289, in <module>\n",
      "    @typeof_impl.register(np.polynomial.polynomial.Polynomial)\n",
      "AttributeError: module 'numpy.polynomial' has no attribute 'polynomial'\n",
      "]\n",
      "[autoreload of numba.core.environment failed: Traceback (most recent call last):\n",
      "  File \"/home/pita/Projects/py_fatigue/.venv/lib/python3.9/site-packages/IPython/extensions/autoreload.py\", line 276, in check\n",
      "    superreload(m, reload, self.old_objects)\n",
      "  File \"/home/pita/Projects/py_fatigue/.venv/lib/python3.9/site-packages/IPython/extensions/autoreload.py\", line 500, in superreload\n",
      "    update_generic(old_obj, new_obj)\n",
      "  File \"/home/pita/Projects/py_fatigue/.venv/lib/python3.9/site-packages/IPython/extensions/autoreload.py\", line 397, in update_generic\n",
      "    update(a, b)\n",
      "  File \"/home/pita/Projects/py_fatigue/.venv/lib/python3.9/site-packages/IPython/extensions/autoreload.py\", line 365, in update_class\n",
      "    update_instances(old, new)\n",
      "  File \"/home/pita/Projects/py_fatigue/.venv/lib/python3.9/site-packages/IPython/extensions/autoreload.py\", line 323, in update_instances\n",
      "    object.__setattr__(ref, \"__class__\", new)\n",
      "TypeError: __class__ assignment: 'Environment' object layout differs from 'Environment'\n",
      "]\n",
      "[autoreload of numba.core.rewrites.static_getitem failed: Traceback (most recent call last):\n",
      "  File \"/home/pita/Projects/py_fatigue/.venv/lib/python3.9/site-packages/IPython/extensions/autoreload.py\", line 276, in check\n",
      "    superreload(m, reload, self.old_objects)\n",
      "  File \"/home/pita/Projects/py_fatigue/.venv/lib/python3.9/site-packages/IPython/extensions/autoreload.py\", line 475, in superreload\n",
      "    module = reload(module)\n",
      "  File \"/home/pita/.pyenv/versions/3.9.19/lib/python3.9/importlib/__init__.py\", line 169, in reload\n",
      "    _bootstrap._exec(spec, module)\n",
      "  File \"<frozen importlib._bootstrap>\", line 613, in _exec\n",
      "  File \"<frozen importlib._bootstrap_external>\", line 850, in exec_module\n",
      "  File \"<frozen importlib._bootstrap>\", line 228, in _call_with_frames_removed\n",
      "  File \"/home/pita/Projects/py_fatigue/.venv/lib/python3.9/site-packages/numba/core/rewrites/static_getitem.py\", line 6, in <module>\n",
      "    class RewriteConstGetitems(Rewrite):\n",
      "  File \"/home/pita/Projects/py_fatigue/.venv/lib/python3.9/site-packages/numba/core/rewrites/registry.py\", line 48, in do_register\n",
      "    raise TypeError('{0} is not a subclass of Rewrite'.format(\n",
      "TypeError: <class 'numba.core.rewrites.static_getitem.RewriteConstGetitems'> is not a subclass of Rewrite\n",
      "]\n",
      "[autoreload of numba.core.rewrites.static_raise failed: Traceback (most recent call last):\n",
      "  File \"/home/pita/Projects/py_fatigue/.venv/lib/python3.9/site-packages/IPython/extensions/autoreload.py\", line 276, in check\n",
      "    superreload(m, reload, self.old_objects)\n",
      "  File \"/home/pita/Projects/py_fatigue/.venv/lib/python3.9/site-packages/IPython/extensions/autoreload.py\", line 475, in superreload\n",
      "    module = reload(module)\n",
      "  File \"/home/pita/.pyenv/versions/3.9.19/lib/python3.9/importlib/__init__.py\", line 169, in reload\n",
      "    _bootstrap._exec(spec, module)\n",
      "  File \"<frozen importlib._bootstrap>\", line 613, in _exec\n",
      "  File \"<frozen importlib._bootstrap_external>\", line 850, in exec_module\n",
      "  File \"<frozen importlib._bootstrap>\", line 228, in _call_with_frames_removed\n",
      "  File \"/home/pita/Projects/py_fatigue/.venv/lib/python3.9/site-packages/numba/core/rewrites/static_raise.py\", line 6, in <module>\n",
      "    class RewriteConstRaises(Rewrite):\n",
      "  File \"/home/pita/Projects/py_fatigue/.venv/lib/python3.9/site-packages/numba/core/rewrites/registry.py\", line 48, in do_register\n",
      "    raise TypeError('{0} is not a subclass of Rewrite'.format(\n",
      "TypeError: <class 'numba.core.rewrites.static_raise.RewriteConstRaises'> is not a subclass of Rewrite\n",
      "]\n",
      "[autoreload of numba.core.rewrites.static_binop failed: Traceback (most recent call last):\n",
      "  File \"/home/pita/Projects/py_fatigue/.venv/lib/python3.9/site-packages/IPython/extensions/autoreload.py\", line 276, in check\n",
      "    superreload(m, reload, self.old_objects)\n",
      "  File \"/home/pita/Projects/py_fatigue/.venv/lib/python3.9/site-packages/IPython/extensions/autoreload.py\", line 475, in superreload\n",
      "    module = reload(module)\n",
      "  File \"/home/pita/.pyenv/versions/3.9.19/lib/python3.9/importlib/__init__.py\", line 169, in reload\n",
      "    _bootstrap._exec(spec, module)\n",
      "  File \"<frozen importlib._bootstrap>\", line 613, in _exec\n",
      "  File \"<frozen importlib._bootstrap_external>\", line 850, in exec_module\n",
      "  File \"<frozen importlib._bootstrap>\", line 228, in _call_with_frames_removed\n",
      "  File \"/home/pita/Projects/py_fatigue/.venv/lib/python3.9/site-packages/numba/core/rewrites/static_binop.py\", line 6, in <module>\n",
      "    class DetectStaticBinops(Rewrite):\n",
      "  File \"/home/pita/Projects/py_fatigue/.venv/lib/python3.9/site-packages/numba/core/rewrites/registry.py\", line 48, in do_register\n",
      "    raise TypeError('{0} is not a subclass of Rewrite'.format(\n",
      "TypeError: <class 'numba.core.rewrites.static_binop.DetectStaticBinops'> is not a subclass of Rewrite\n",
      "]\n",
      "[autoreload of numba.core.rewrites.ir_print failed: Traceback (most recent call last):\n",
      "  File \"/home/pita/Projects/py_fatigue/.venv/lib/python3.9/site-packages/IPython/extensions/autoreload.py\", line 276, in check\n",
      "    superreload(m, reload, self.old_objects)\n",
      "  File \"/home/pita/Projects/py_fatigue/.venv/lib/python3.9/site-packages/IPython/extensions/autoreload.py\", line 475, in superreload\n",
      "    module = reload(module)\n",
      "  File \"/home/pita/.pyenv/versions/3.9.19/lib/python3.9/importlib/__init__.py\", line 169, in reload\n",
      "    _bootstrap._exec(spec, module)\n",
      "  File \"<frozen importlib._bootstrap>\", line 613, in _exec\n",
      "  File \"<frozen importlib._bootstrap_external>\", line 850, in exec_module\n",
      "  File \"<frozen importlib._bootstrap>\", line 228, in _call_with_frames_removed\n",
      "  File \"/home/pita/Projects/py_fatigue/.venv/lib/python3.9/site-packages/numba/core/rewrites/ir_print.py\", line 6, in <module>\n",
      "    class RewritePrintCalls(Rewrite):\n",
      "  File \"/home/pita/Projects/py_fatigue/.venv/lib/python3.9/site-packages/numba/core/rewrites/registry.py\", line 48, in do_register\n",
      "    raise TypeError('{0} is not a subclass of Rewrite'.format(\n",
      "TypeError: <class 'numba.core.rewrites.ir_print.RewritePrintCalls'> is not a subclass of Rewrite\n",
      "]\n",
      "[autoreload of numba.core.tracing failed: Traceback (most recent call last):\n",
      "  File \"/home/pita/Projects/py_fatigue/.venv/lib/python3.9/site-packages/IPython/extensions/autoreload.py\", line 276, in check\n",
      "    superreload(m, reload, self.old_objects)\n",
      "  File \"/home/pita/Projects/py_fatigue/.venv/lib/python3.9/site-packages/IPython/extensions/autoreload.py\", line 500, in superreload\n",
      "    update_generic(old_obj, new_obj)\n",
      "  File \"/home/pita/Projects/py_fatigue/.venv/lib/python3.9/site-packages/IPython/extensions/autoreload.py\", line 397, in update_generic\n",
      "    update(a, b)\n",
      "  File \"/home/pita/Projects/py_fatigue/.venv/lib/python3.9/site-packages/IPython/extensions/autoreload.py\", line 365, in update_class\n",
      "    update_instances(old, new)\n",
      "  File \"/home/pita/Projects/py_fatigue/.venv/lib/python3.9/site-packages/IPython/extensions/autoreload.py\", line 323, in update_instances\n",
      "    object.__setattr__(ref, \"__class__\", new)\n",
      "TypeError: can't apply this __setattr__ to TLS object\n",
      "]\n",
      "[autoreload of numba.core.typing.npydecl failed: Traceback (most recent call last):\n",
      "  File \"/home/pita/Projects/py_fatigue/.venv/lib/python3.9/site-packages/IPython/extensions/autoreload.py\", line 276, in check\n",
      "    superreload(m, reload, self.old_objects)\n",
      "  File \"/home/pita/Projects/py_fatigue/.venv/lib/python3.9/site-packages/IPython/extensions/autoreload.py\", line 475, in superreload\n",
      "    module = reload(module)\n",
      "  File \"/home/pita/.pyenv/versions/3.9.19/lib/python3.9/importlib/__init__.py\", line 169, in reload\n",
      "    _bootstrap._exec(spec, module)\n",
      "  File \"<frozen importlib._bootstrap>\", line 613, in _exec\n",
      "  File \"<frozen importlib._bootstrap_external>\", line 850, in exec_module\n",
      "  File \"<frozen importlib._bootstrap>\", line 228, in _call_with_frames_removed\n",
      "  File \"/home/pita/Projects/py_fatigue/.venv/lib/python3.9/site-packages/numba/core/typing/npydecl.py\", line 659, in <module>\n",
      "    @infer_global(pndindex)\n",
      "  File \"/home/pita/Projects/py_fatigue/.venv/lib/python3.9/site-packages/numba/core/typing/templates.py\", line 1286, in register_global\n",
      "    raise ValueError(\"%r is not globally reachable as '%s.%s'\"\n",
      "ValueError: <module 'numba.misc.special' from '/home/pita/Projects/py_fatigue/.venv/lib/python3.9/site-packages/numba/misc/special.py'> is not globally reachable as 'numba.misc.special.pndindex'\n",
      "]\n",
      "[autoreload of numba.core.typing.builtins failed: Traceback (most recent call last):\n",
      "  File \"/home/pita/Projects/py_fatigue/.venv/lib/python3.9/site-packages/IPython/extensions/autoreload.py\", line 276, in check\n",
      "    superreload(m, reload, self.old_objects)\n",
      "  File \"/home/pita/Projects/py_fatigue/.venv/lib/python3.9/site-packages/IPython/extensions/autoreload.py\", line 475, in superreload\n",
      "    module = reload(module)\n",
      "  File \"/home/pita/.pyenv/versions/3.9.19/lib/python3.9/importlib/__init__.py\", line 169, in reload\n",
      "    _bootstrap._exec(spec, module)\n",
      "  File \"<frozen importlib._bootstrap>\", line 613, in _exec\n",
      "  File \"<frozen importlib._bootstrap_external>\", line 850, in exec_module\n",
      "  File \"<frozen importlib._bootstrap>\", line 228, in _call_with_frames_removed\n",
      "  File \"/home/pita/Projects/py_fatigue/.venv/lib/python3.9/site-packages/numba/core/typing/builtins.py\", line 72, in <module>\n",
      "    @infer_global(prange, typing_key=prange)\n",
      "  File \"/home/pita/Projects/py_fatigue/.venv/lib/python3.9/site-packages/numba/core/typing/templates.py\", line 1286, in register_global\n",
      "    raise ValueError(\"%r is not globally reachable as '%s.%s'\"\n",
      "ValueError: <module 'numba.misc.special' from '/home/pita/Projects/py_fatigue/.venv/lib/python3.9/site-packages/numba/misc/special.py'> is not globally reachable as 'numba.misc.special.prange'\n",
      "]\n",
      "[autoreload of numba.core.typed_passes failed: Traceback (most recent call last):\n",
      "  File \"/home/pita/Projects/py_fatigue/.venv/lib/python3.9/site-packages/IPython/extensions/autoreload.py\", line 276, in check\n",
      "    superreload(m, reload, self.old_objects)\n",
      "  File \"/home/pita/Projects/py_fatigue/.venv/lib/python3.9/site-packages/IPython/extensions/autoreload.py\", line 500, in superreload\n",
      "    update_generic(old_obj, new_obj)\n",
      "  File \"/home/pita/Projects/py_fatigue/.venv/lib/python3.9/site-packages/IPython/extensions/autoreload.py\", line 397, in update_generic\n",
      "    update(a, b)\n",
      "  File \"/home/pita/Projects/py_fatigue/.venv/lib/python3.9/site-packages/IPython/extensions/autoreload.py\", line 365, in update_class\n",
      "    update_instances(old, new)\n",
      "  File \"/home/pita/Projects/py_fatigue/.venv/lib/python3.9/site-packages/IPython/extensions/autoreload.py\", line 323, in update_instances\n",
      "    object.__setattr__(ref, \"__class__\", new)\n",
      "TypeError: __class__ assignment: 'NativeLowering' object layout differs from 'NativeLowering'\n",
      "]\n",
      "[autoreload of numba.np.ufunc.dufunc failed: Traceback (most recent call last):\n",
      "  File \"/home/pita/Projects/py_fatigue/.venv/lib/python3.9/site-packages/IPython/extensions/autoreload.py\", line 276, in check\n",
      "    superreload(m, reload, self.old_objects)\n",
      "  File \"/home/pita/Projects/py_fatigue/.venv/lib/python3.9/site-packages/IPython/extensions/autoreload.py\", line 500, in superreload\n",
      "    update_generic(old_obj, new_obj)\n",
      "  File \"/home/pita/Projects/py_fatigue/.venv/lib/python3.9/site-packages/IPython/extensions/autoreload.py\", line 397, in update_generic\n",
      "    update(a, b)\n",
      "  File \"/home/pita/Projects/py_fatigue/.venv/lib/python3.9/site-packages/IPython/extensions/autoreload.py\", line 349, in update_class\n",
      "    if update_generic(old_obj, new_obj):\n",
      "  File \"/home/pita/Projects/py_fatigue/.venv/lib/python3.9/site-packages/IPython/extensions/autoreload.py\", line 397, in update_generic\n",
      "    update(a, b)\n",
      "  File \"/home/pita/Projects/py_fatigue/.venv/lib/python3.9/site-packages/IPython/extensions/autoreload.py\", line 309, in update_function\n",
      "    setattr(old, name, getattr(new, name))\n",
      "ValueError: __init__() requires a code object with 0 free vars, not 1\n",
      "]\n",
      "[autoreload of numba failed: Traceback (most recent call last):\n",
      "  File \"/home/pita/Projects/py_fatigue/.venv/lib/python3.9/site-packages/IPython/extensions/autoreload.py\", line 276, in check\n",
      "    superreload(m, reload, self.old_objects)\n",
      "  File \"/home/pita/Projects/py_fatigue/.venv/lib/python3.9/site-packages/IPython/extensions/autoreload.py\", line 475, in superreload\n",
      "    module = reload(module)\n",
      "  File \"/home/pita/.pyenv/versions/3.9.19/lib/python3.9/importlib/__init__.py\", line 169, in reload\n",
      "    _bootstrap._exec(spec, module)\n",
      "  File \"<frozen importlib._bootstrap>\", line 613, in _exec\n",
      "  File \"<frozen importlib._bootstrap_external>\", line 850, in exec_module\n",
      "  File \"<frozen importlib._bootstrap>\", line 228, in _call_with_frames_removed\n",
      "  File \"/home/pita/Projects/py_fatigue/.venv/lib/python3.9/site-packages/numba/__init__.py\", line 235, in <module>\n",
      "    _ensure_llvm()\n",
      "  File \"/home/pita/Projects/py_fatigue/.venv/lib/python3.9/site-packages/numba/__init__.py\", line 183, in _ensure_llvm\n",
      "    raise ImportError(msg)\n",
      "ImportError: Numba requires at least version 14.0.0 of LLVM.\n",
      "Installed llvmlite is built against version 11.1.0.\n",
      "Please update llvmlite.\n",
      "]\n",
      "[autoreload of numba.cpython.slicing failed: Traceback (most recent call last):\n",
      "  File \"/home/pita/Projects/py_fatigue/.venv/lib/python3.9/site-packages/IPython/extensions/autoreload.py\", line 276, in check\n",
      "    superreload(m, reload, self.old_objects)\n",
      "  File \"/home/pita/Projects/py_fatigue/.venv/lib/python3.9/site-packages/IPython/extensions/autoreload.py\", line 475, in superreload\n",
      "    module = reload(module)\n",
      "  File \"/home/pita/.pyenv/versions/3.9.19/lib/python3.9/importlib/__init__.py\", line 169, in reload\n",
      "    _bootstrap._exec(spec, module)\n",
      "  File \"<frozen importlib._bootstrap>\", line 613, in _exec\n",
      "  File \"<frozen importlib._bootstrap_external>\", line 850, in exec_module\n",
      "  File \"<frozen importlib._bootstrap>\", line 228, in _call_with_frames_removed\n",
      "  File \"/home/pita/Projects/py_fatigue/.venv/lib/python3.9/site-packages/numba/cpython/slicing.py\", line 298, in <module>\n",
      "    @lower_cast(types.misc.SliceLiteral, types.SliceType)\n",
      "AttributeError: module 'numba.core.types' has no attribute 'misc'\n",
      "]\n"
     ]
    },
    {
     "ename": "",
     "evalue": "",
     "output_type": "error",
     "traceback": [
      "\u001b[1;31mThe Kernel crashed while executing code in the current cell or a previous cell. \n",
      "\u001b[1;31mPlease review the code in the cell(s) to identify a possible cause of the failure. \n",
      "\u001b[1;31mClick <a href='https://aka.ms/vscodeJupyterKernelCrash'>here</a> for more info. \n",
      "\u001b[1;31mView Jupyter <a href='command:jupyter.viewOutput'>log</a> for further details."
     ]
    }
   ],
   "source": [
    "%load_ext autoreload\n",
    "%autoreload 2\n",
    "# %matplotlib inline"
   ]
  },
  {
   "cell_type": "code",
   "execution_count": 2,
   "metadata": {
    "ExecuteTime": {
     "end_time": "2022-06-16T14:47:10.411668Z",
     "start_time": "2022-06-16T14:47:09.429114Z"
    }
   },
   "outputs": [
    {
     "name": "stdout",
     "output_type": "stream",
     "text": [
      "PROJECT_PATH = /home/pita/Projects/py_fatigue\n",
      "Platform: Linux-6.5.0-1025-oem-x86_64-with-glibc2.35\n",
      "Python version: 3.9.19 (main, Sep  2 2024, 18:33:51) \n",
      "[GCC 11.4.0]\n",
      "numpy version: 1.23.5\n"
     ]
    }
   ],
   "source": [
    "import datetime as dt\n",
    "import os\n",
    "import platform\n",
    "import sys\n",
    "import numpy as np\n",
    "import pandas as pd\n",
    "import matplotlib.pyplot as plt\n",
    "import plotly.graph_objs as go\n",
    "\n",
    "PROJECT_PATH = os.path.dirname(os.getcwd())\n",
    "print(f'PROJECT_PATH = {PROJECT_PATH}')\n",
    "\n",
    "if not PROJECT_PATH in sys.path:\n",
    "    sys.path.append(PROJECT_PATH)\n",
    "    \n",
    "print('Platform:', platform.platform())\n",
    "print('Python version:', sys.version)\n",
    "print('numpy version:', np.__version__)\n",
    "np.set_printoptions(threshold=sys.maxsize)"
   ]
  },
  {
   "cell_type": "code",
   "execution_count": 3,
   "metadata": {
    "ExecuteTime": {
     "end_time": "2022-06-16T14:47:10.475159Z",
     "start_time": "2022-06-16T14:47:10.411668Z"
    }
   },
   "outputs": [],
   "source": [
    "#matplotlib tweaking\n",
    "plt.rcParams['figure.figsize'] = (10.5/2.514/0.7, 4.5/2.514/0.7)\n",
    "plt.rcParams[\"font.family\"] = \"Sans\"\n",
    "plt.rcParams[\"font.size\"] = 10\n",
    "# plt.rcParams[\"axes.grid\"] = True\n",
    "# plt.rcParams['grid.color'] = \"#CCCCCC\"\n",
    "# plt.rcParams['grid.linestyle'] = \"-\"\n",
    "# plt.rcParams['grid.color'] = \"#DDDDDD\"\n",
    "# plt.rcParams['grid.linestyle'] = \"-\"\n",
    "plt.rcParams['axes.spines.right'] = False\n",
    "plt.rcParams['axes.spines.top'] = False\n",
    "plt.rcParams['lines.markersize'] = 3\n",
    "plt.rcParams['xtick.bottom'] = False\n",
    "plt.rcParams['xtick.labelbottom'] = True\n",
    "plt.rcParams['ytick.left'] = False\n",
    "plt.rcParams['ytick.labelleft'] = True"
   ]
  },
  {
   "cell_type": "markdown",
   "metadata": {},
   "source": [
    "## Import and use the functionality"
   ]
  },
  {
   "cell_type": "code",
   "execution_count": 5,
   "metadata": {
    "ExecuteTime": {
     "end_time": "2022-06-16T14:47:12.468692Z",
     "start_time": "2022-06-16T14:47:11.748517Z"
    }
   },
   "outputs": [],
   "source": [
    "# Use the package\n",
    "import py_fatigue as pf\n",
    "import py_fatigue.cycle_count.rainflow as rf\n",
    "import py_fatigue.cycle_count.histogram as ht\n",
    "from py_fatigue.version import parse_version, __version__\n",
    "v = parse_version(__version__)"
   ]
  },
  {
   "cell_type": "code",
   "execution_count": 6,
   "metadata": {},
   "outputs": [
    {
     "name": "stdout",
     "output_type": "stream",
     "text": [
      "Version(major=1, minor=0, patch=20, release=None, num=None)\n"
     ]
    }
   ],
   "source": [
    "print(v)"
   ]
  },
  {
   "cell_type": "code",
   "execution_count": null,
   "metadata": {},
   "outputs": [],
   "source": []
  }
 ],
 "metadata": {
  "hide_input": false,
  "kernelspec": {
   "display_name": "Python 3 (ipykernel)",
   "language": "python",
   "name": "python3"
  },
  "language_info": {
   "codemirror_mode": {
    "name": "ipython",
    "version": 3
   },
   "file_extension": ".py",
   "mimetype": "text/x-python",
   "name": "python",
   "nbconvert_exporter": "python",
   "pygments_lexer": "ipython3",
   "version": "3.9.19"
  },
  "latex_envs": {
   "LaTeX_envs_menu_present": true,
   "autoclose": false,
   "autocomplete": true,
   "bibliofile": "biblio.bib",
   "cite_by": "apalike",
   "current_citInitial": 1,
   "eqLabelWithNumbers": true,
   "eqNumInitial": 1,
   "hotkeys": {
    "equation": "Ctrl-E",
    "itemize": "Ctrl-I"
   },
   "labels_anchors": false,
   "latex_user_defs": false,
   "report_style_numbering": false,
   "user_envs_cfg": false
  },
  "toc": {
   "base_numbering": 1,
   "nav_menu": {},
   "number_sections": true,
   "sideBar": true,
   "skip_h1_title": true,
   "title_cell": "Table of Contents",
   "title_sidebar": "Contents",
   "toc_cell": true,
   "toc_position": {},
   "toc_section_display": true,
   "toc_window_display": false
  }
 },
 "nbformat": 4,
 "nbformat_minor": 2
}
